Workbook

Sheet orders
A1: ID | B1: accoutid | C1: CLIENTE | D1: FECHA | E1: TOTAL | F1: ESTADO | G1: FLOW | H1: CANAL | I1: CAJAS
A2: DIR-#1003 | B2: {=IFERROR( INDEX(accounts!A:A, MATCH(CLEAN(TRIM(UPPER(C2))), CLEAN(TRIM(UPPER(accounts!B:B))), 0)), "shopify" )} -> shopify | C2: Venta Online | D2: 45803 | E2: 47.99 | F2: paid | G2: DIRECT | H2: ONLINE | I2: 0.0
A3: DIR-nan | B3: {=IFERROR( INDEX(accounts!A:A, MATCH(CLEAN(TRIM(UPPER(C3))), CLEAN(TRIM(UPPER(accounts!B:B))), 0)), "shopify" )} -> acc_147 | C3: Ingo Gestión de activos | D3: 45834 | E3: 288.0 | F3: paid | G3: DIRECT | H3: PRIVADA | I3: 6.0
A4: DIR-nan | B4: {=IFERROR( INDEX(accounts!A:A, MATCH(CLEAN(TRIM(UPPER(C4))), CLEAN(TRIM(UPPER(accounts!B:B))), 0)), "shopify" )} -> acc_147 | C4: Ingo Gestión de activos | D4: 45834 | E4: 480.0 | F4: paid | G4: DIRECT | H4: PRIVADA | I4: 10.0
A5: DIR-#1005 | B5: {=IFERROR( INDEX(accounts!A:A, MATCH(CLEAN(TRIM(UPPER(C5))), CLEAN(TRIM(UPPER(accounts!B:B))), 0)), "shopify" )} -> shopify | C5: Venta Online | D5: 45835 | E5: 175.25 | F5: paid | G5: DIRECT | H5: ONLINE | I5: 2.0
A6: DIR-nan | B6: {=IFERROR( INDEX(accounts!A:A, MATCH(CLEAN(TRIM(UPPER(C6))), CLEAN(TRIM(UPPER(accounts!B:B))), 0)), "shopify" )} -> acc_147 | C6: Ingo Gestión de activos | D6: 45839 | E6: 960.0 | F6: paid | G6: DIRECT | H6: PRIVADA | I6: 20.0
A7: DIR-nan | B7: {=IFERROR( INDEX(accounts!A:A, MATCH(CLEAN(TRIM(UPPER(C7))), CLEAN(TRIM(UPPER(accounts!B:B))), 0)), "shopify" )} -> acc_147 | C7: Ingo Gestión de activos | D7: 45842 | E7: 480.0 | F7: paid | G7: DIRECT | H7: PRIVADA | I7: 10.0
A8: DIR-#1007 | B8: {=IFERROR( INDEX(accounts!A:A, MATCH(CLEAN(TRIM(UPPER(C8))), CLEAN(TRIM(UPPER(accounts!B:B))), 0)), "shopify" )} -> shopify | C8: Venta Online | D8: 45843 | E8: 124.37 | F8: paid | G8: DIRECT | H8: ONLINE | I8: 1.0
A9: DIR-#1007 | B9: {=IFERROR( INDEX(accounts!A:A, MATCH(CLEAN(TRIM(UPPER(C9))), CLEAN(TRIM(UPPER(accounts!B:B))), 0)), "shopify" )} -> shopify | C9: Venta Online | D9: 45855 | E9: 54.5 | F9: paid | G9: DIRECT | H9: ONLINE | I9: 0.0
A10: DIR-#1008 | B10: {=IFERROR( INDEX(accounts!A:A, MATCH(CLEAN(TRIM(UPPER(C10))), CLEAN(TRIM(UPPER(accounts!B:B))), 0)), "shopify" )} -> shopify | C10: Venta Online | D10: 45856 | E10: 105.6 | F10: paid | G10: DIRECT | H10: ONLINE | I10: 1.0
A11: DIR-#1009 | B11: {=IFERROR( INDEX(accounts!A:A, MATCH(CLEAN(TRIM(UPPER(C11))), CLEAN(TRIM(UPPER(accounts!B:B))), 0)), "shopify" )} -> shopify | C11: Venta Online | D11: 45856 | E11: 144.0 | F11: paid | G11: DIRECT | H11: ONLINE | I11: 1.0
A12: DIR-#1010 | B12: {=IFERROR( INDEX(accounts!A:A, MATCH(CLEAN(TRIM(UPPER(C12))), CLEAN(TRIM(UPPER(accounts!B:B))), 0)), "shopify" )} -> shopify | C12: Venta Online | D12: 45859 | E12: 132.0 | F12: paid | G12: DIRECT | H12: ONLINE | I12: 1.0
A13: DIR-#1011 | B13: {=IFERROR( INDEX(accounts!A:A, MATCH(CLEAN(TRIM(UPPER(C13))), CLEAN(TRIM(UPPER(accounts!B:B))), 0)), "shopify" )} -> shopify | C13: Venta Online | D13: 45862 | E13: 132.0 | F13: paid | G13: DIRECT | H13: ONLINE | I13: 1.0
... A27: DIR-#1024 | B27: {=IFERROR( INDEX(accounts!A:A, MATCH(CLEAN(TRIM(UPPER(C27))), CLEAN(TRIM(UPPER(accounts!B:B))), 0)), "shopify" )} -> shopify | C27: Venta Online | D27: 45873 | E27: 105.6 | F27: paid | G27: DIRECT | H27: ONLINE | I27: 1.0
A28: DIR-#1025 | B28: {=IFERROR( INDEX(accounts!A:A, MATCH(CLEAN(TRIM(UPPER(C28))), CLEAN(TRIM(UPPER(accounts!B:B))), 0)), "shopify" )} -> shopify | C28: Venta Online | D28: 45873 | E28: 45803 | F28: paid | G28: DIRECT | H28: ONLINE | I28: 0.0
A29: DIR-#1026 | B29: {=IFERROR( INDEX(accounts!A:A, MATCH(CLEAN(TRIM(UPPER(C29))), CLEAN(TRIM(UPPER(accounts!B:B))), 0)), "shopify" )} -> shopify | C29: Venta Online | D29: 45874 | E29: 105.6 | F29: paid | G29: DIRECT | H29: ONLINE | I29: 1.0
A30: DIR-#1027 | B30: {=IFERROR( INDEX(accounts!A:A, MATCH(CLEAN(TRIM(UPPER(C30))), CLEAN(TRIM(UPPER(accounts!B:B))), 0)), "shopify" )} -> shopify | C30: Venta Online | D30: 45874 | E30: 44.9 | F30: paid | G30: DIRECT | H30: ONLINE | I30: 0.0
A31: DIR-#1028 | B31: {=IFERROR( INDEX(accounts!A:A, MATCH(CLEAN(TRIM(UPPER(C31))), CLEAN(TRIM(UPPER(accounts!B:B))), 0)), "shopify" )} -> shopify | C31: Venta Online | D31: 45875 | E31: 105.6 | F31: paid | G31: DIRECT | H31: ONLINE | I31: 1.0
A32: DIR-#1029 | B32: {=IFERROR( INDEX(accounts!A:A, MATCH(CLEAN(TRIM(UPPER(C32))), CLEAN(TRIM(UPPER(accounts!B:B))), 0)), "shopify" )} -> shopify | C32: Venta Online | D32: 45875 | E32: 105.6 | F32: paid | G32: DIRECT | H32: ONLINE | I32: 1.0
A33: DIR-#1031 | B33: {=IFERROR( INDEX(accounts!A:A, MATCH(CLEAN(TRIM(UPPER(C33))), CLEAN(TRIM(UPPER(accounts!B:B))), 0)), "shopify" )} -> shopify | C33: Venta Online | D33: 45878 | E33: 44.9 | F33: paid | G33: DIRECT | H33: ONLINE | I33: 0.0
A34: DIR-#1032 | B34: {=IFERROR( INDEX(accounts!A:A, MATCH(CLEAN(TRIM(UPPER(C34))), CLEAN(TRIM(UPPER(accounts!B:B))), 0)), "shopify" )} -> shopify | C34: Venta Online | D34: 45879 | E34: 105.6 | F34: paid | G34: DIRECT | H34: ONLINE | I34: 1.0
A35: DIR-nan | B35: {=IFERROR( INDEX(accounts!A:A, MATCH(CLEAN(TRIM(UPPER(C35))), CLEAN(TRIM(UPPER(accounts!B:B))), 0)), "shopify" )} -> shopify | C35: Venta Online | D35: 45879 | E35: 47.78 | F35: paid | G35: DIRECT | H35: ONLINE | I35: 0.0
A36: DIR-#1035 | B36: {=IFERROR( INDEX(accounts!A:A, MATCH(CLEAN(TRIM(UPPER(C36))), CLEAN(TRIM(UPPER(accounts!B:B))), 0)), "shopify" )} -> shopify | C36: Venta Online | D36: 45886 | E36: 105.6 | F36: paid | G36: DIRECT | H36: ONLINE | I36: 1.0
A37: DIR-#1036 | B37: {=IFERROR( INDEX(accounts!A:A, MATCH(CLEAN(TRIM(UPPER(C37))), CLEAN(TRIM(UPPER(accounts!B:B))), 0)), "shopify" )} -> shopify | C37: Venta Online | D37: 45888 | E37: 132.0 | F37: paid | G37: DIRECT | H37: ONLINE | I37: 1.0
A38: DIR-#1038 | B38: {=IFERROR( INDEX(accounts!A:A, MATCH(CLEAN(TRIM(UPPER(C38))), CLEAN(TRIM(UPPER(accounts!B:B))), 0)), "shopify" )} -> shopify | C38: Venta Online | D38: 45889 | E38: 105.6 | F38: paid | G38: DIRECT | H38: ONLINE | I38: 1.0
A39: DIR-#1040 | B39: {=IFERROR( INDEX(accounts!A:A, MATCH(CLEAN(TRIM(UPPER(C39))), CLEAN(TRIM(UPPER(accounts!B:B))), 0)), "shopify" )} -> shopify | C39: Venta Online | D39: 45891 | E39: 66.0 | F39: paid | G39: DIRECT | H39: ONLINE | I39: 1.0
A40: DIR-#1041 | B40: {=IFERROR( INDEX(accounts!A:A, MATCH(CLEAN(TRIM(UPPER(C40))), CLEAN(TRIM(UPPER(accounts!B:B))), 0)), "shopify" )} -> shopify | C40: Venta Online | D40: 45892 | E40: 132.0 | F40: paid | G40: DIRECT | H40: ONLINE | I40: 1.0
A41: DIR-#1042 | B41: {=IFERROR( INDEX(accounts!A:A, MATCH(CLEAN(TRIM(UPPER(C41))), CLEAN(TRIM(UPPER(accounts!B:B))), 0)), "shopify" )} -> shopify | C41: Venta Online | D41: 45894 | E41: 105.6 | F41: paid | G41: DIRECT | H41: ONLINE | I41: 1.0
A42: DIR-#1043 | B42: {=IFERROR( INDEX(accounts!A:A, MATCH(CLEAN(TRIM(UPPER(C42))), CLEAN(TRIM(UPPER(accounts!B:B))), 0)), "shopify" )} -> shopify | C42: Venta Online | D42: 45896 | E42: 45803 | F42: paid | G42: DIRECT | H42: ONLINE | I42: 0.0
A43: DIR-#1045 | B43: {=IFERROR( INDEX(accounts!A:A, MATCH(CLEAN(TRIM(UPPER(C43))), CLEAN(TRIM(UPPER(accounts!B:B))), 0)), "shopify" )} -> shopify | C43: Venta Online | D43: 45897 | E43: 132.0 | F43: paid | G43: DIRECT | H43: ONLINE | I43: 1.0
A44: DIR-#1046 | B44: {=IFERROR( INDEX(accounts!A:A, MATCH(CLEAN(TRIM(UPPER(C44))), CLEAN(TRIM(UPPER(accounts!B:B))), 0)), "shopify" )} -> shopify | C44: Venta Online | D44: 45900 | E44: 105.6 | F44: paid | G44: DIRECT | H44: ONLINE | I44: 1.0
A45: DIR-#1047 | B45: {=IFERROR( INDEX(accounts!A:A, MATCH(CLEAN(TRIM(UPPER(C45))), CLEAN(TRIM(UPPER(accounts!B:B))), 0)), "shopify" )} -> shopify | C45: Venta Online | D45: 45900 | E45: 45808 | F45: paid | G45: DIRECT | H45: ONLINE | I45: 0.0
A46: DIR-#1048 | B46: {=IFERROR( INDEX(accounts!A:A, MATCH(CLEAN(TRIM(UPPER(C46))), CLEAN(TRIM(UPPER(accounts!B:B))), 0)), "shopify" )} -> shopify | C46: Venta Online | D46: 45900 | E46: 660.0 | F46: paid | G46: DIRECT | H46: ONLINE | I46: 5.0
A47: DIR-#1049 | B47: {=IFERROR( INDEX(accounts!A:A, MATCH(CLEAN(TRIM(UPPER(C47))), CLEAN(TRIM(UPPER(accounts!B:B))), 0)), "shopify" )} -> shopify | C47: Venta Online | D47: 45902 | E47: 105.6 | F47: paid | G47: DIRECT | H47: ONLINE | I47: 1.0
A48: DIR-#1050 | B48: {=IFERROR( INDEX(accounts!A:A, MATCH(CLEAN(TRIM(UPPER(C48))), CLEAN(TRIM(UPPER(accounts!B:B))), 0)), "shopify" )} -> shopify | C48: Venta Online | D48: 45905 | E48: 54.5 | F48: paid | G48: DIRECT | H48: ONLINE | I48: 0.33
A49: DIR-F25006 | B49: {=IFERROR( INDEX(accounts!A:A, MATCH(CLEAN(TRIM(UPPER(C49))), CLEAN(TRIM(UPPER(accounts!B:B))), 0)), "shopify" )} -> acc_149 | C49: Servilline Foods | D49: 45908 | E49: 1380.0 | F49: paid | G49: DIRECT | H49: DISTRIBUIDOR | I49: 20.0
A50: DIR-F25005 | B50: {=IFERROR( INDEX(accounts!A:A, MATCH(CLEAN(TRIM(UPPER(C50))), CLEAN(TRIM(UPPER(accounts!B:B))), 0)), "shopify" )} -> acc_057 | C50: Real Club de Golf de Sotongrande | D50: 45909 | E50: 508.2 | F50: paid | G50: DIRECT | H50: HORECA | I50: 5.0
A51: DIR-#1051 | B51: {=IFERROR( INDEX(accounts!A:A, MATCH(CLEAN(TRIM(UPPER(C51))), CLEAN(TRIM(UPPER(accounts!B:B))), 0)), "shopify" )} -> shopify | C51: Venta Online | D51: 45909 | E51: 342.2 | F51: paid | G51: DIRECT | H51: ONLINE | I51: 4.0
A52: DIR-F25008 | B52: {=IFERROR( INDEX(accounts!A:A, MATCH(CLEAN(TRIM(UPPER(C52))), CLEAN(TRIM(UPPER(accounts!B:B))), 0)), "shopify" )} -> acc_150 | C52: Devnis Menorca | D52: 45912 | E52: 1043.62 | F52: paid | G52: DIRECT | H52: DISTRIBUIDOR | I52: 15.0
A53: DIR-#1052 | B53: {=IFERROR( INDEX(accounts!A:A, MATCH(CLEAN(TRIM(UPPER(C53))), CLEAN(TRIM(UPPER(accounts!B:B))), 0)), "shopify" )} -> shopify | C53: Venta Online | D53: 45912 | E53: 54.5 | F53: paid | G53: DIRECT | H53: ONLINE | I53: 0.33
...

Sheet Hoja 1
A1: id | B1: Nombre | C1: source | D1: ownerId | E1: Segment | F1: Stage | G1: FLow | H1: distributorPartyId | I1: Contacto | K1: FLow | L1: Stage | M1: Distribuidor | N1: ownerId | O1: ownerId | Q1: City
A2: acc_001 | B2: Chez Pepito | C2: =IFERROR(__xludf.DUMMYFUNCTION("IFS( REGEXMATCH(LOWER(TRIM(N2)),""nico""), ""us_001"", REGEXMATCH(LOWER(TRIM(N2)),""alfonso""), ""us_002"", REGEXMATCH(LOWER(TRIM(N2)),""patxi""), ""us_003"", REGEXMATCH(LOWER(TRIM(N2)),""martin""), ""us_004"", TRUE, ""us_999"" )"),"us_002") -> us_002 | D2: =IFERROR(__xludf.DUMMYFUNCTION("ARRAYFORMULA( IF(N2:N999="""", , IFS( REGEXMATCH(LOWER(TRIM(N2:N999)),""nico""), ""us_001"", REGEXMATCH(LOWER(TRIM(N2:N999)),""alfonso""), ""us_002"", REGEXMATCH(LOWER(TRIM(N2:N999)),""patxi""), ""us_003"", REGEXMATCH(LOW"&"ER(TRIM(N2:N999)),""martin""), ""us_004"", TRUE, ""us_999"" ) ) ) "),"us_002") -> us_002 | E2: Horeca | F2: =IFERROR(__xludf.DUMMYFUNCTION("LET( s, UPPER(TRIM(N2)), IF(REGEXMATCH(s,""CLOSED.*WON""), ""ACTIVA"", IF(REGEXMATCH(s,""CLOSED.*LOST""), ""FALLIDA"", IF(REGEXMATCH(s,""CONTACT.*NEXT.*SEASON""), ""POTENCIAL"", IF(REGEXMATCH(s,""\bLEAD\b""), ""LEAD"", IF(REGEXMATCH(s,""INTERE"&"ST|POTENTIAL""), ""SEGUIMIENTO"", ""SEGUIMIENTO""))))) ) "),"SEGUIMIENTO") -> SEGUIMIENTO | G2: Placement | H2: =IFERROR(__xludf.DUMMYFUNCTION("IFS( REGEXMATCH(LOWER(TRIM(U2)),""barcelona""), ""acc_139"", REGEXMATCH(LOWER(TRIM(U2)),""madrid""), ""acc_148"", REGEXMATCH(LOWER(TRIM(U2)),""zaragoza""), ""acc_149"", REGEXMATCH(LOWER(TRIM(U2)),""ibiza""), ""acc_140"", REGEXMATCH(LOWER(TRIM(U2"&")),""mallorca""), ""acc_140"", REGEXMATCH(LOWER(TRIM(U2)),""menorca""), ""acc_150"", TRUE, """" ) "),"acc_148") -> acc_148 | I2: Romin | K2: Placement | L2: =IFERROR(__xludf.DUMMYFUNCTION("LET( s, UPPER(TRIM(T2)), IF(REGEXMATCH(s,""CLOSED.*WON""), ""ACTIVA"", IF(REGEXMATCH(s,""CLOSED.*LOST""), ""FALLIDA"", IF(REGEXMATCH(s,""CONTACT.*NEXT.*SEASON""), ""POTENCIAL"", IF(REGEXMATCH(s,""\bLEAD\b""), ""LEAD"", IF(REGEXMATCH(s,""INTERE"&"ST|POTENTIAL""), ""SEGUIMIENTO"", ""SEGUIMIENTO""))))) ) "),"ACTIVA") -> ACTIVA | N2: =V2 -> Alfonso | O2: =W2 -> 2 cajas | S2: TRUE | T2: CLOSED / WON | U2: Madrid | V2: Alfonso | W2: 2 cajas
A3: acc_002 | B3: eMeBe | C3: =IFERROR(__xludf.DUMMYFUNCTION("IFS( REGEXMATCH(LOWER(TRIM(N3)),""nico""), ""us_001"", REGEXMATCH(LOWER(TRIM(N3)),""alfonso""), ""us_002"", REGEXMATCH(LOWER(TRIM(N3)),""patxi""), ""us_003"", REGEXMATCH(LOWER(TRIM(N3)),""martin""), ""us_004"", TRUE, ""us_999"" )"),"us_001") -> us_001 | D3: =IFERROR(__xludf.DUMMYFUNCTION("""COMPUTED_VALUE"""),"us_001") -> us_001 | E3: Horeca | F3: =IFERROR(__xludf.DUMMYFUNCTION("LET( s, UPPER(TRIM(N3)), IF(REGEXMATCH(s,""CLOSED.*WON""), ""ACTIVA"", IF(REGEXMATCH(s,""CLOSED.*LOST""), ""FALLIDA"", IF(REGEXMATCH(s,""CONTACT.*NEXT.*SEASON""), ""POTENCIAL"", IF(REGEXMATCH(s,""\bLEAD\b""), ""LEAD"", IF(REGEXMATCH(s,""INTERE"&"ST|POTENTIAL""), ""SEGUIMIENTO"", ""SEGUIMIENTO""))))) ) "),"SEGUIMIENTO") -> SEGUIMIENTO | G3: Placement | H3: =IFERROR(__xludf.DUMMYFUNCTION("IFS( REGEXMATCH(LOWER(TRIM(U3)),""barcelona""), ""acc_139"", REGEXMATCH(LOWER(TRIM(U3)),""madrid""), ""acc_148"", REGEXMATCH(LOWER(TRIM(U3)),""zaragoza""), ""acc_149"", REGEXMATCH(LOWER(TRIM(U3)),""ibiza""), ""acc_140"", REGEXMATCH(LOWER(TRIM(U3"&")),""mallorca""), ""acc_140"", REGEXMATCH(LOWER(TRIM(U3)),""menorca""), ""acc_150"", TRUE, """" ) "),"acc_148") -> acc_148 | I3: Miguel | K3: Placement | L3: =IFERROR(__xludf.DUMMYFUNCTION("LET( s, UPPER(TRIM(T3)), IF(REGEXMATCH(s,""CLOSED.*WON""), ""ACTIVA"", IF(REGEXMATCH(s,""CLOSED.*LOST""), ""FALLIDA"", IF(REGEXMATCH(s,""CONTACT.*NEXT.*SEASON""), ""POTENCIAL"", IF(REGEXMATCH(s,""\bLEAD\b""), ""LEAD"", IF(REGEXMATCH(s,""INTERE"&"ST|POTENTIAL""), ""SEGUIMIENTO"", ""SEGUIMIENTO""))))) ) "),"ACTIVA") -> ACTIVA | N3: =V3 -> Nico | O3: =W3 -> 2 cajas | S3: TRUE | T3: CLOSED / WON | U3: Madrid | V3: Nico | W3: 2 cajas | Y3: 8 Vasos + Cubitera grande
A4: acc_003 | B4: Morenas | C4: =IFERROR(__xludf.DUMMYFUNCTION("IFS( REGEXMATCH(LOWER(TRIM(N4)),""nico""), ""us_001"", REGEXMATCH(LOWER(TRIM(N4)),""alfonso""), ""us_002"", REGEXMATCH(LOWER(TRIM(N4)),""patxi""), ""us_003"", REGEXMATCH(LOWER(TRIM(N4)),""martin""), ""us_004"", TRUE, ""us_999"" )"),"us_001") -> us_001 | D4: =IFERROR(__xludf.DUMMYFUNCTION("""COMPUTED_VALUE"""),"us_001") -> us_001 | E4: Horeca | F4: =IFERROR(__xludf.DUMMYFUNCTION("LET( s, UPPER(TRIM(N4)), IF(REGEXMATCH(s,""CLOSED.*WON""), ""ACTIVA"", IF(REGEXMATCH(s,""CLOSED.*LOST""), ""FALLIDA"", IF(REGEXMATCH(s,""CONTACT.*NEXT.*SEASON""), ""POTENCIAL"", IF(REGEXMATCH(s,""\bLEAD\b""), ""LEAD"", IF(REGEXMATCH(s,""INTERE"&"ST|POTENTIAL""), ""SEGUIMIENTO"", ""SEGUIMIENTO""))))) ) "),"SEGUIMIENTO") -> SEGUIMIENTO | G4: Placement | H4: =IFERROR(__xludf.DUMMYFUNCTION("IFS( REGEXMATCH(LOWER(TRIM(U4)),""barcelona""), ""acc_139"", REGEXMATCH(LOWER(TRIM(U4)),""madrid""), ""acc_148"", REGEXMATCH(LOWER(TRIM(U4)),""zaragoza""), ""acc_149"", REGEXMATCH(LOWER(TRIM(U4)),""ibiza""), ""acc_140"", REGEXMATCH(LOWER(TRIM(U4"&")),""mallorca""), ""acc_140"", REGEXMATCH(LOWER(TRIM(U4)),""menorca""), ""acc_150"", TRUE, """" ) "),"acc_148") -> acc_148 | I4: Eduardo Rozo | K4: Placement | L4: =IFERROR(__xludf.DUMMYFUNCTION("LET( s, UPPER(TRIM(T4)), IF(REGEXMATCH(s,""CLOSED.*WON""), ""ACTIVA"", IF(REGEXMATCH(s,""CLOSED.*LOST""), ""FALLIDA"", IF(REGEXMATCH(s,""CONTACT.*NEXT.*SEASON""), ""POTENCIAL"", IF(REGEXMATCH(s,""\bLEAD\b""), ""LEAD"", IF(REGEXMATCH(s,""INTERE"&"ST|POTENTIAL""), ""SEGUIMIENTO"", ""SEGUIMIENTO""))))) ) "),"ACTIVA") -> ACTIVA | N4: =V4 -> Nico | O4: =W4 | S4: TRUE | T4: CLOSED / WON | U4: Madrid | V4: Nico
A5: acc_004 | B5: Chakana | C5: =IFERROR(__xludf.DUMMYFUNCTION("IFS( REGEXMATCH(LOWER(TRIM(N5)),""nico""), ""us_001"", REGEXMATCH(LOWER(TRIM(N5)),""alfonso""), ""us_002"", REGEXMATCH(LOWER(TRIM(N5)),""patxi""), ""us_003"", REGEXMATCH(LOWER(TRIM(N5)),""martin""), ""us_004"", TRUE, ""us_999"" )"),"us_001") -> us_001 | D5: =IFERROR(__xludf.DUMMYFUNCTION("""COMPUTED_VALUE"""),"us_001") -> us_001 | E5: Horeca | F5: =IFERROR(__xludf.DUMMYFUNCTION("LET( s, UPPER(TRIM(N5)), IF(REGEXMATCH(s,""CLOSED.*WON""), ""ACTIVA"", IF(REGEXMATCH(s,""CLOSED.*LOST""), ""FALLIDA"", IF(REGEXMATCH(s,""CONTACT.*NEXT.*SEASON""), ""POTENCIAL"", IF(REGEXMATCH(s,""\bLEAD\b""), ""LEAD"", IF(REGEXMATCH(s,""INTERE"&"ST|POTENTIAL""), ""SEGUIMIENTO"", ""SEGUIMIENTO""))))) ) "),"SEGUIMIENTO") -> SEGUIMIENTO | G5: Placement | H5: =IFERROR(__xludf.DUMMYFUNCTION("IFS( REGEXMATCH(LOWER(TRIM(U5)),""barcelona""), ""acc_139"", REGEXMATCH(LOWER(TRIM(U5)),""madrid""), ""acc_148"", REGEXMATCH(LOWER(TRIM(U5)),""zaragoza""), ""acc_149"", REGEXMATCH(LOWER(TRIM(U5)),""ibiza""), ""acc_140"", REGEXMATCH(LOWER(TRIM(U5"&")),""mallorca""), ""acc_140"", REGEXMATCH(LOWER(TRIM(U5)),""menorca""), ""acc_150"", TRUE, """" ) "),"acc_149") -> acc_149 | I5: Omar | K5: Placement | L5: =IFERROR(__xludf.DUMMYFUNCTION("LET( s, UPPER(TRIM(T5)), IF(REGEXMATCH(s,""CLOSED.*WON""), ""ACTIVA"", IF(REGEXMATCH(s,""CLOSED.*LOST""), ""FALLIDA"", IF(REGEXMATCH(s,""CONTACT.*NEXT.*SEASON""), ""POTENCIAL"", IF(REGEXMATCH(s,""\bLEAD\b""), ""LEAD"", IF(REGEXMATCH(s,""INTERE"&"ST|POTENTIAL""), ""SEGUIMIENTO"", ""SEGUIMIENTO""))))) ) "),"ACTIVA") -> ACTIVA | N5: =V5 -> Nico | O5: =W5 | S5: TRUE | T5: CLOSED / WON | U5: Zaragoza | V5: Nico
A6: acc_005 | B6: El Gordo Velazquez | C6: =IFERROR(__xludf.DUMMYFUNCTION("IFS( REGEXMATCH(LOWER(TRIM(N6)),""nico""), ""us_001"", REGEXMATCH(LOWER(TRIM(N6)),""alfonso""), ""us_002"", REGEXMATCH(LOWER(TRIM(N6)),""patxi""), ""us_003"", REGEXMATCH(LOWER(TRIM(N6)),""martin""), ""us_004"", TRUE, ""us_999"" )"),"us_001") -> us_001 | D6: =IFERROR(__xludf.DUMMYFUNCTION("""COMPUTED_VALUE"""),"us_001") -> us_001 | E6: Horeca | F6: =IFERROR(__xludf.DUMMYFUNCTION("LET( s, UPPER(TRIM(N6)), IF(REGEXMATCH(s,""CLOSED.*WON""), ""ACTIVA"", IF(REGEXMATCH(s,""CLOSED.*LOST""), ""FALLIDA"", IF(REGEXMATCH(s,""CONTACT.*NEXT.*SEASON""), ""POTENCIAL"", IF(REGEXMATCH(s,""\bLEAD\b""), ""LEAD"", IF(REGEXMATCH(s,""INTERE"&"ST|POTENTIAL""), ""SEGUIMIENTO"", ""SEGUIMIENTO""))))) ) "),"SEGUIMIENTO") -> SEGUIMIENTO | G6: Placement | H6: =IFERROR(__xludf.DUMMYFUNCTION("IFS( REGEXMATCH(LOWER(TRIM(U6)),""barcelona""), ""acc_139"", REGEXMATCH(LOWER(TRIM(U6)),""madrid""), ""acc_148"", REGEXMATCH(LOWER(TRIM(U6)),""zaragoza""), ""acc_149"", REGEXMATCH(LOWER(TRIM(U6)),""ibiza""), ""acc_140"", REGEXMATCH(LOWER(TRIM(U6"&")),""mallorca""), ""acc_140"", REGEXMATCH(LOWER(TRIM(U6)),""menorca""), ""acc_150"", TRUE, """" ) "),"acc_148") -> acc_148 | I6: Jan Paulo y Javier | K6: Placement | L6: =IFERROR(__xludf.DUMMYFUNCTION("LET( s, UPPER(TRIM(T6)), IF(REGEXMATCH(s,""CLOSED.*WON""), ""ACTIVA"", IF(REGEXMATCH(s,""CLOSED.*LOST""), ""FALLIDA"", IF(REGEXMATCH(s,""CONTACT.*NEXT.*SEASON""), ""POTENCIAL"", IF(REGEXMATCH(s,""\bLEAD\b""), ""LEAD"", IF(REGEXMATCH(s,""INTERE"&"ST|POTENTIAL""), ""SEGUIMIENTO"", ""SEGUIMIENTO""))))) ) "),"ACTIVA") -> ACTIVA | N6: =V6 -> Nico | O6: =W6 | S6: TRUE | T6: CLOSED / WON | U6: Madrid | V6: Nico
A7: acc_006 | B7: Sabodiga | C7: =IFERROR(__xludf.DUMMYFUNCTION("IFS( REGEXMATCH(LOWER(TRIM(N7)),""nico""), ""us_001"", REGEXMATCH(LOWER(TRIM(N7)),""alfonso""), ""us_002"", REGEXMATCH(LOWER(TRIM(N7)),""patxi""), ""us_003"", REGEXMATCH(LOWER(TRIM(N7)),""martin""), ""us_004"", TRUE, ""us_999"" )"),"us_003") -> us_003 | D7: =IFERROR(__xludf.DUMMYFUNCTION("""COMPUTED_VALUE"""),"us_003") -> us_003 | E7: Horeca | F7: =IFERROR(__xludf.DUMMYFUNCTION("LET( s, UPPER(TRIM(N7)), IF(REGEXMATCH(s,""CLOSED.*WON""), ""ACTIVA"", IF(REGEXMATCH(s,""CLOSED.*LOST""), ""FALLIDA"", IF(REGEXMATCH(s,""CONTACT.*NEXT.*SEASON""), ""POTENCIAL"", IF(REGEXMATCH(s,""\bLEAD\b""), ""LEAD"", IF(REGEXMATCH(s,""INTERE"&"ST|POTENTIAL""), ""SEGUIMIENTO"", ""SEGUIMIENTO""))))) ) "),"SEGUIMIENTO") -> SEGUIMIENTO | G7: Placement | H7: =IFERROR(__xludf.DUMMYFUNCTION("IFS( REGEXMATCH(LOWER(TRIM(U7)),""barcelona""), ""acc_139"", REGEXMATCH(LOWER(TRIM(U7)),""madrid""), ""acc_148"", REGEXMATCH(LOWER(TRIM(U7)),""zaragoza""), ""acc_149"", REGEXMATCH(LOWER(TRIM(U7)),""ibiza""), ""acc_140"", REGEXMATCH(LOWER(TRIM(U7"&")),""mallorca""), ""acc_140"", REGEXMATCH(LOWER(TRIM(U7)),""menorca""), ""acc_150"", TRUE, """" ) "),"acc_150") -> acc_150 | K7: Placement | L7: =IFERROR(__xludf.DUMMYFUNCTION("LET( s, UPPER(TRIM(T7)), IF(REGEXMATCH(s,""CLOSED.*WON""), ""ACTIVA"", IF(REGEXMATCH(s,""CLOSED.*LOST""), ""FALLIDA"", IF(REGEXMATCH(s,""CONTACT.*NEXT.*SEASON""), ""POTENCIAL"", IF(REGEXMATCH(s,""\bLEAD\b""), ""LEAD"", IF(REGEXMATCH(s,""INTERE"&"ST|POTENTIAL""), ""SEGUIMIENTO"", ""SEGUIMIENTO""))))) ) "),"ACTIVA") -> ACTIVA | N7: =V7 -> Patxi | O7: =W7 | S7: FALSE | T7: CLOSED / WON | U7: Menorca | V7: Patxi
A8: acc_007 | B8: Senor Bigote | C8: =IFERROR(__xludf.DUMMYFUNCTION("IFS( REGEXMATCH(LOWER(TRIM(N8)),""nico""), ""us_001"", REGEXMATCH(LOWER(TRIM(N8)),""alfonso""), ""us_002"", REGEXMATCH(LOWER(TRIM(N8)),""patxi""), ""us_003"", REGEXMATCH(LOWER(TRIM(N8)),""martin""), ""us_004"", TRUE, ""us_999"" )"),"us_003") -> us_003 | D8: =IFERROR(__xludf.DUMMYFUNCTION("""COMPUTED_VALUE"""),"us_003") -> us_003 | E8: Horeca | F8: =IFERROR(__xludf.DUMMYFUNCTION("LET( s, UPPER(TRIM(N8)), IF(REGEXMATCH(s,""CLOSED.*WON""), ""ACTIVA"", IF(REGEXMATCH(s,""CLOSED.*LOST""), ""FALLIDA"", IF(REGEXMATCH(s,""CONTACT.*NEXT.*SEASON""), ""POTENCIAL"", IF(REGEXMATCH(s,""\bLEAD\b""), ""LEAD"", IF(REGEXMATCH(s,""INTERE"&"ST|POTENTIAL""), ""SEGUIMIENTO"", ""SEGUIMIENTO""))))) ) "),"SEGUIMIENTO") -> SEGUIMIENTO | G8: Placement | H8: =IFERROR(__xludf.DUMMYFUNCTION("IFS( REGEXMATCH(LOWER(TRIM(U8)),""barcelona""), ""acc_139"", REGEXMATCH(LOWER(TRIM(U8)),""madrid""), ""acc_148"", REGEXMATCH(LOWER(TRIM(U8)),""zaragoza""), ""acc_149"", REGEXMATCH(LOWER(TRIM(U8)),""ibiza""), ""acc_140"", REGEXMATCH(LOWER(TRIM(U8"&")),""mallorca""), ""acc_140"", REGEXMATCH(LOWER(TRIM(U8)),""menorca""), ""acc_150"", TRUE, """" ) "),"acc_150") -> acc_150 | I8: Jesus | K8: Placement | L8: =IFERROR(__xludf.DUMMYFUNCTION("LET( s, UPPER(TRIM(T8)), IF(REGEXMATCH(s,""CLOSED.*WON""), ""ACTIVA"", IF(REGEXMATCH(s,""CLOSED.*LOST""), ""FALLIDA"", IF(REGEXMATCH(s,""CONTACT.*NEXT.*SEASON""), ""POTENCIAL"", IF(REGEXMATCH(s,""\bLEAD\b""), ""LEAD"", IF(REGEXMATCH(s,""INTERE"&"ST|POTENTIAL""), ""SEGUIMIENTO"", ""SEGUIMIENTO""))))) ) "),"ACTIVA") -> ACTIVA | N8: =V8 -> Patxi | O8: =W8 | S8: FALSE | T8: CLOSED / WON | U8: Menorca | V8: Patxi
A9: acc_008 | B9: Cristanal y Gradinata | C9: =IFERROR(__xludf.DUMMYFUNCTION("IFS( REGEXMATCH(LOWER(TRIM(N9)),""nico""), ""us_001"", REGEXMATCH(LOWER(TRIM(N9)),""alfonso""), ""us_002"", REGEXMATCH(LOWER(TRIM(N9)),""patxi""), ""us_003"", REGEXMATCH(LOWER(TRIM(N9)),""martin""), ""us_004"", TRUE, ""us_999"" )"),"us_003") -> us_003 | D9: =IFERROR(__xludf.DUMMYFUNCTION("""COMPUTED_VALUE"""),"us_003") -> us_003 | E9: Horeca | F9: =IFERROR(__xludf.DUMMYFUNCTION("LET( s, UPPER(TRIM(N9)), IF(REGEXMATCH(s,""CLOSED.*WON""), ""ACTIVA"", IF(REGEXMATCH(s,""CLOSED.*LOST""), ""FALLIDA"", IF(REGEXMATCH(s,""CONTACT.*NEXT.*SEASON""), ""POTENCIAL"", IF(REGEXMATCH(s,""\bLEAD\b""), ""LEAD"", IF(REGEXMATCH(s,""INTERE"&"ST|POTENTIAL""), ""SEGUIMIENTO"", ""SEGUIMIENTO""))))) ) "),"SEGUIMIENTO") -> SEGUIMIENTO | G9: Placement | H9: =IFERROR(__xludf.DUMMYFUNCTION("IFS( REGEXMATCH(LOWER(TRIM(U9)),""barcelona""), ""acc_139"", REGEXMATCH(LOWER(TRIM(U9)),""madrid""), ""acc_148"", REGEXMATCH(LOWER(TRIM(U9)),""zaragoza""), ""acc_149"", REGEXMATCH(LOWER(TRIM(U9)),""ibiza""), ""acc_140"", REGEXMATCH(LOWER(TRIM(U9"&")),""mallorca""), ""acc_140"", REGEXMATCH(LOWER(TRIM(U9)),""menorca""), ""acc_150"", TRUE, """" ) "),"acc_150") -> acc_150 | K9: Placement | L9: =IFERROR(__xludf.DUMMYFUNCTION("LET( s, UPPER(TRIM(T9)), IF(REGEXMATCH(s,""CLOSED.*WON""), ""ACTIVA"", IF(REGEXMATCH(s,""CLOSED.*LOST""), ""FALLIDA"", IF(REGEXMATCH(s,""CONTACT.*NEXT.*SEASON""), ""POTENCIAL"", IF(REGEXMATCH(s,""\bLEAD\b""), ""LEAD"", IF(REGEXMATCH(s,""INTERE"&"ST|POTENTIAL""), ""SEGUIMIENTO"", ""SEGUIMIENTO""))))) ) "),"ACTIVA") -> ACTIVA | N9: =V9 -> Patxi | O9: =W9 | S9: FALSE | T9: CLOSED / WON | U9: Menorca | V9: Patxi
A10: acc_009 | B10: Oysters | C10: =IFERROR(__xludf.DUMMYFUNCTION("IFS( REGEXMATCH(LOWER(TRIM(N10)),""nico""), ""us_001"", REGEXMATCH(LOWER(TRIM(N10)),""alfonso""), ""us_002"", REGEXMATCH(LOWER(TRIM(N10)),""patxi""), ""us_003"", REGEXMATCH(LOWER(TRIM(N10)),""martin""), ""us_004"", TRUE, ""us_999"" )"),"us_003") -> us_003 | D10: =IFERROR(__xludf.DUMMYFUNCTION("""COMPUTED_VALUE"""),"us_003") -> us_003 | E10: Horeca | F10: =IFERROR(__xludf.DUMMYFUNCTION("LET( s, UPPER(TRIM(N10)), IF(REGEXMATCH(s,""CLOSED.*WON""), ""ACTIVA"", IF(REGEXMATCH(s,""CLOSED.*LOST""), ""FALLIDA"", IF(REGEXMATCH(s,""CONTACT.*NEXT.*SEASON""), ""POTENCIAL"", IF(REGEXMATCH(s,""\bLEAD\b""), ""LEAD"", IF(REGEXMATCH(s,""INTER"&"EST|POTENTIAL""), ""SEGUIMIENTO"", ""SEGUIMIENTO""))))) ) "),"SEGUIMIENTO") -> SEGUIMIENTO | G10: Placement | H10: =IFERROR(__xludf.DUMMYFUNCTION("IFS( REGEXMATCH(LOWER(TRIM(U10)),""barcelona""), ""acc_139"", REGEXMATCH(LOWER(TRIM(U10)),""madrid""), ""acc_148"", REGEXMATCH(LOWER(TRIM(U10)),""zaragoza""), ""acc_149"", REGEXMATCH(LOWER(TRIM(U10)),""ibiza""), ""acc_140"", REGEXMATCH(LOWER(TRI"&"M(U10)),""mallorca""), ""acc_140"", REGEXMATCH(LOWER(TRIM(U10)),""menorca""), ""acc_150"", TRUE, """" ) "),"acc_150") -> acc_150 | I10: Tobi | K10: Placement | L10: =IFERROR(__xludf.DUMMYFUNCTION("LET( s, UPPER(TRIM(T10)), IF(REGEXMATCH(s,""CLOSED.*WON""), ""ACTIVA"", IF(REGEXMATCH(s,""CLOSED.*LOST""), ""FALLIDA"", IF(REGEXMATCH(s,""CONTACT.*NEXT.*SEASON""), ""POTENCIAL"", IF(REGEXMATCH(s,""\bLEAD\b""), ""LEAD"", IF(REGEXMATCH(s,""INTER"&"EST|POTENTIAL""), ""SEGUIMIENTO"", ""SEGUIMIENTO""))))) ) "),"ACTIVA") -> ACTIVA | N10: =V10 -> Patxi | O10: =W10 | S10: FALSE | T10: CLOSED / WON | U10: Menorca | V10: Patxi | Y10: 6 vasos | AA10: Carrer de Bastió, 7, 07703 Maó, Illes Balears
A11: acc_010 | B11: Sa Tintina | C11: =IFERROR(__xludf.DUMMYFUNCTION("IFS( REGEXMATCH(LOWER(TRIM(N11)),""nico""), ""us_001"", REGEXMATCH(LOWER(TRIM(N11)),""alfonso""), ""us_002"", REGEXMATCH(LOWER(TRIM(N11)),""patxi""), ""us_003"", REGEXMATCH(LOWER(TRIM(N11)),""martin""), ""us_004"", TRUE, ""us_999"" )"),"us_003") -> us_003 | D11: =IFERROR(__xludf.DUMMYFUNCTION("""COMPUTED_VALUE"""),"us_003") -> us_003 | E11: Horeca | F11: =IFERROR(__xludf.DUMMYFUNCTION("LET( s, UPPER(TRIM(N11)), IF(REGEXMATCH(s,""CLOSED.*WON""), ""ACTIVA"", IF(REGEXMATCH(s,""CLOSED.*LOST""), ""FALLIDA"", IF(REGEXMATCH(s,""CONTACT.*NEXT.*SEASON""), ""POTENCIAL"", IF(REGEXMATCH(s,""\bLEAD\b""), ""LEAD"", IF(REGEXMATCH(s,""INTER"&"EST|POTENTIAL""), ""SEGUIMIENTO"", ""SEGUIMIENTO""))))) ) "),"SEGUIMIENTO") -> SEGUIMIENTO | G11: Placement | H11: =IFERROR(__xludf.DUMMYFUNCTION("IFS( REGEXMATCH(LOWER(TRIM(U11)),""barcelona""), ""acc_139"", REGEXMATCH(LOWER(TRIM(U11)),""madrid""), ""acc_148"", REGEXMATCH(LOWER(TRIM(U11)),""zaragoza""), ""acc_149"", REGEXMATCH(LOWER(TRIM(U11)),""ibiza""), ""acc_140"", REGEXMATCH(LOWER(TRI"&"M(U11)),""mallorca""), ""acc_140"", REGEXMATCH(LOWER(TRIM(U11)),""menorca""), ""acc_150"", TRUE, """" ) "),"acc_150") -> acc_150 | I11: Alex | K11: Placement | L11: =IFERROR(__xludf.DUMMYFUNCTION("LET( s, UPPER(TRIM(T11)), IF(REGEXMATCH(s,""CLOSED.*WON""), ""ACTIVA"", IF(REGEXMATCH(s,""CLOSED.*LOST""), ""FALLIDA"", IF(REGEXMATCH(s,""CONTACT.*NEXT.*SEASON""), ""POTENCIAL"", IF(REGEXMATCH(s,""\bLEAD\b""), ""LEAD"", IF(REGEXMATCH(s,""INTER"&"EST|POTENTIAL""), ""SEGUIMIENTO"", ""SEGUIMIENTO""))))) ) "),"ACTIVA") -> ACTIVA | N11: =V11 -> Patxi | O11: =W11 | S11: FALSE | T11: CLOSED / WON | U11: Menorca | V11: Patxi
A12: acc_011 | B12: Aqui hay Tomate | C12: =IFERROR(__xludf.DUMMYFUNCTION("IFS( REGEXMATCH(LOWER(TRIM(N12)),""nico""), ""us_001"", REGEXMATCH(LOWER(TRIM(N12)),""alfonso""), ""us_002"", REGEXMATCH(LOWER(TRIM(N12)),""patxi""), ""us_003"", REGEXMATCH(LOWER(TRIM(N12)),""martin""), ""us_004"", TRUE, ""us_999"" )"),"us_003") -> us_003 | D12: =IFERROR(__xludf.DUMMYFUNCTION("""COMPUTED_VALUE"""),"us_003") -> us_003 | E12: Horeca | F12: =IFERROR(__xludf.DUMMYFUNCTION("LET( s, UPPER(TRIM(N12)), IF(REGEXMATCH(s,""CLOSED.*WON""), ""ACTIVA"", IF(REGEXMATCH(s,""CLOSED.*LOST""), ""FALLIDA"", IF(REGEXMATCH(s,""CONTACT.*NEXT.*SEASON""), ""POTENCIAL"", IF(REGEXMATCH(s,""\bLEAD\b""), ""LEAD"", IF(REGEXMATCH(s,""INTER"&"EST|POTENTIAL""), ""SEGUIMIENTO"", ""SEGUIMIENTO""))))) ) "),"SEGUIMIENTO") -> SEGUIMIENTO | G12: Placement | H12: =IFERROR(__xludf.DUMMYFUNCTION("IFS( REGEXMATCH(LOWER(TRIM(U12)),""barcelona""), ""acc_139"", REGEXMATCH(LOWER(TRIM(U12)),""madrid""), ""acc_148"", REGEXMATCH(LOWER(TRIM(U12)),""zaragoza""), ""acc_149"", REGEXMATCH(LOWER(TRIM(U12)),""ibiza""), ""acc_140"", REGEXMATCH(LOWER(TRI"&"M(U12)),""mallorca""), ""acc_140"", REGEXMATCH(LOWER(TRIM(U12)),""menorca""), ""acc_150"", TRUE, """" ) "),"acc_150") -> acc_150 | K12: Placement | L12: =IFERROR(__xludf.DUMMYFUNCTION("LET( s, UPPER(TRIM(T12)), IF(REGEXMATCH(s,""CLOSED.*WON""), ""ACTIVA"", IF(REGEXMATCH(s,""CLOSED.*LOST""), ""FALLIDA"", IF(REGEXMATCH(s,""CONTACT.*NEXT.*SEASON""), ""POTENCIAL"", IF(REGEXMATCH(s,""\bLEAD\b""), ""LEAD"", IF(REGEXMATCH(s,""INTER"&"EST|POTENTIAL""), ""SEGUIMIENTO"", ""SEGUIMIENTO""))))) ) "),"ACTIVA") -> ACTIVA | N12: =V12 -> Patxi | O12: =W12 | S12: FALSE | T12: CLOSED / WON | U12: Menorca | V12: Patxi
A13: acc_012 | B13: Cova den Xoroi | C13: =IFERROR(__xludf.DUMMYFUNCTION("IFS( REGEXMATCH(LOWER(TRIM(N13)),""nico""), ""us_001"", REGEXMATCH(LOWER(TRIM(N13)),""alfonso""), ""us_002"", REGEXMATCH(LOWER(TRIM(N13)),""patxi""), ""us_003"", REGEXMATCH(LOWER(TRIM(N13)),""martin""), ""us_004"", TRUE, ""us_999"" )"),"us_003") -> us_003 | D13: =IFERROR(__xludf.DUMMYFUNCTION("""COMPUTED_VALUE"""),"us_003") -> us_003 | E13: Horeca | F13: =IFERROR(__xludf.DUMMYFUNCTION("LET( s, UPPER(TRIM(N13)), IF(REGEXMATCH(s,""CLOSED.*WON""), ""ACTIVA"", IF(REGEXMATCH(s,""CLOSED.*LOST""), ""FALLIDA"", IF(REGEXMATCH(s,""CONTACT.*NEXT.*SEASON""), ""POTENCIAL"", IF(REGEXMATCH(s,""\bLEAD\b""), ""LEAD"", IF(REGEXMATCH(s,""INTER"&"EST|POTENTIAL""), ""SEGUIMIENTO"", ""SEGUIMIENTO""))))) ) "),"SEGUIMIENTO") -> SEGUIMIENTO | G13: Placement | H13: =IFERROR(__xludf.DUMMYFUNCTION("IFS( REGEXMATCH(LOWER(TRIM(U13)),""barcelona""), ""acc_139"", REGEXMATCH(LOWER(TRIM(U13)),""madrid""), ""acc_148"", REGEXMATCH(LOWER(TRIM(U13)),""zaragoza""), ""acc_149"", REGEXMATCH(LOWER(TRIM(U13)),""ibiza""), ""acc_140"", REGEXMATCH(LOWER(TRI"&"M(U13)),""mallorca""), ""acc_140"", REGEXMATCH(LOWER(TRIM(U13)),""menorca""), ""acc_150"", TRUE, """" ) "),"acc_150") -> acc_150 | K13: Placement | L13: =IFERROR(__xludf.DUMMYFUNCTION("LET( s, UPPER(TRIM(T13)), IF(REGEXMATCH(s,""CLOSED.*WON""), ""ACTIVA"", IF(REGEXMATCH(s,""CLOSED.*LOST""), ""FALLIDA"", IF(REGEXMATCH(s,""CONTACT.*NEXT.*SEASON""), ""POTENCIAL"", IF(REGEXMATCH(s,""\bLEAD\b""), ""LEAD"", IF(REGEXMATCH(s,""INTER"&"EST|POTENTIAL""), ""SEGUIMIENTO"", ""SEGUIMIENTO""))))) ) "),"ACTIVA") -> ACTIVA | N13: =V13 -> Patxi | O13: =W13 | S13: FALSE | T13: CLOSED / WON | U13: Menorca | V13: Patxi
A14: acc_013 | B14: Madrid al Cielo | C14: =IFERROR(__xludf.DUMMYFUNCTION("IFS( REGEXMATCH(LOWER(TRIM(N14)),""nico""), ""us_001"", REGEXMATCH(LOWER(TRIM(N14)),""alfonso""), ""us_002"", REGEXMATCH(LOWER(TRIM(N14)),""patxi""), ""us_003"", REGEXMATCH(LOWER(TRIM(N14)),""martin""), ""us_004"", TRUE, ""us_999"" )"),"us_003") -> us_003 | D14: =IFERROR(__xludf.DUMMYFUNCTION("""COMPUTED_VALUE"""),"us_003") -> us_003 | E14: Horeca | F14: =IFERROR(__xludf.DUMMYFUNCTION("LET( s, UPPER(TRIM(N14)), IF(REGEXMATCH(s,""CLOSED.*WON""), ""ACTIVA"", IF(REGEXMATCH(s,""CLOSED.*LOST""), ""FALLIDA"", IF(REGEXMATCH(s,""CONTACT.*NEXT.*SEASON""), ""POTENCIAL"", IF(REGEXMATCH(s,""\bLEAD\b""), ""LEAD"", IF(REGEXMATCH(s,""INTER"&"EST|POTENTIAL""), ""SEGUIMIENTO"", ""SEGUIMIENTO""))))) ) "),"SEGUIMIENTO") -> SEGUIMIENTO | G14: Placement | H14: =IFERROR(__xludf.DUMMYFUNCTION("IFS( REGEXMATCH(LOWER(TRIM(U14)),""barcelona""), ""acc_139"", REGEXMATCH(LOWER(TRIM(U14)),""madrid""), ""acc_148"", REGEXMATCH(LOWER(TRIM(U14)),""zaragoza""), ""acc_149"", REGEXMATCH(LOWER(TRIM(U14)),""ibiza""), ""acc_140"", REGEXMATCH(LOWER(TRI"&"M(U14)),""mallorca""), ""acc_140"", REGEXMATCH(LOWER(TRIM(U14)),""menorca""), ""acc_150"", TRUE, """" ) "),"acc_150") -> acc_150 | K14: Placement | L14: =IFERROR(__xludf.DUMMYFUNCTION("LET( s, UPPER(TRIM(T14)), IF(REGEXMATCH(s,""CLOSED.*WON""), ""ACTIVA"", IF(REGEXMATCH(s,""CLOSED.*LOST""), ""FALLIDA"", IF(REGEXMATCH(s,""CONTACT.*NEXT.*SEASON""), ""POTENCIAL"", IF(REGEXMATCH(s,""\bLEAD\b""), ""LEAD"", IF(REGEXMATCH(s,""INTER"&"EST|POTENTIAL""), ""SEGUIMIENTO"", ""SEGUIMIENTO""))))) ) "),"ACTIVA") -> ACTIVA | N14: =V14 -> Patxi | O14: =W14 | S14: FALSE | T14: CLOSED / WON | U14: Menorca | V14: Patxi
A15: acc_014 | B15: Bar Augustin | C15: =IFERROR(__xludf.DUMMYFUNCTION("IFS( REGEXMATCH(LOWER(TRIM(N15)),""nico""), ""us_001"", REGEXMATCH(LOWER(TRIM(N15)),""alfonso""), ""us_002"", REGEXMATCH(LOWER(TRIM(N15)),""patxi""), ""us_003"", REGEXMATCH(LOWER(TRIM(N15)),""martin""), ""us_004"", TRUE, ""us_999"" )"),"us_003") -> us_003 | D15: =IFERROR(__xludf.DUMMYFUNCTION("""COMPUTED_VALUE"""),"us_003") -> us_003 | E15: Horeca | F15: =IFERROR(__xludf.DUMMYFUNCTION("LET( s, UPPER(TRIM(N15)), IF(REGEXMATCH(s,""CLOSED.*WON""), ""ACTIVA"", IF(REGEXMATCH(s,""CLOSED.*LOST""), ""FALLIDA"", IF(REGEXMATCH(s,""CONTACT.*NEXT.*SEASON""), ""POTENCIAL"", IF(REGEXMATCH(s,""\bLEAD\b""), ""LEAD"", IF(REGEXMATCH(s,""INTER"&"EST|POTENTIAL""), ""SEGUIMIENTO"", ""SEGUIMIENTO""))))) ) "),"SEGUIMIENTO") -> SEGUIMIENTO | G15: Placement | H15: =IFERROR(__xludf.DUMMYFUNCTION("IFS( REGEXMATCH(LOWER(TRIM(U15)),""barcelona""), ""acc_139"", REGEXMATCH(LOWER(TRIM(U15)),""madrid""), ""acc_148"", REGEXMATCH(LOWER(TRIM(U15)),""zaragoza""), ""acc_149"", REGEXMATCH(LOWER(TRIM(U15)),""ibiza""), ""acc_140"", REGEXMATCH(LOWER(TRI"&"M(U15)),""mallorca""), ""acc_140"", REGEXMATCH(LOWER(TRIM(U15)),""menorca""), ""acc_150"", TRUE, """" ) "),"acc_150") -> acc_150 | I15: Patri | K15: Placement | L15: =IFERROR(__xludf.DUMMYFUNCTION("LET( s, UPPER(TRIM(T15)), IF(REGEXMATCH(s,""CLOSED.*WON""), ""ACTIVA"", IF(REGEXMATCH(s,""CLOSED.*LOST""), ""FALLIDA"", IF(REGEXMATCH(s,""CONTACT.*NEXT.*SEASON""), ""POTENCIAL"", IF(REGEXMATCH(s,""\bLEAD\b""), ""LEAD"", IF(REGEXMATCH(s,""INTER"&"EST|POTENTIAL""), ""SEGUIMIENTO"", ""SEGUIMIENTO""))))) ) "),"ACTIVA") -> ACTIVA | N15: =V15 -> Patxi | O15: =W15 | S15: FALSE | T15: CLOSED / WON | U15: Menorca | V15: Patxi
A16: acc_015 | B16: Supermercado melo | C16: =IFERROR(__xludf.DUMMYFUNCTION("IFS( REGEXMATCH(LOWER(TRIM(N16)),""nico""), ""us_001"", REGEXMATCH(LOWER(TRIM(N16)),""alfonso""), ""us_002"", REGEXMATCH(LOWER(TRIM(N16)),""patxi""), ""us_003"", REGEXMATCH(LOWER(TRIM(N16)),""martin""), ""us_004"", TRUE, ""us_999"" )"),"us_001") -> us_001 | D16: =IFERROR(__xludf.DUMMYFUNCTION("""COMPUTED_VALUE"""),"us_001") -> us_001 | E16: Horeca | F16: =IFERROR(__xludf.DUMMYFUNCTION("LET( s, UPPER(TRIM(N16)), IF(REGEXMATCH(s,""CLOSED.*WON""), ""ACTIVA"", IF(REGEXMATCH(s,""CLOSED.*LOST""), ""FALLIDA"", IF(REGEXMATCH(s,""CONTACT.*NEXT.*SEASON""), ""POTENCIAL"", IF(REGEXMATCH(s,""\bLEAD\b""), ""LEAD"", IF(REGEXMATCH(s,""INTER"&"EST|POTENTIAL""), ""SEGUIMIENTO"", ""SEGUIMIENTO""))))) ) "),"SEGUIMIENTO") -> SEGUIMIENTO | G16: Placement | H16: =IFERROR(__xludf.DUMMYFUNCTION("IFS( REGEXMATCH(LOWER(TRIM(U16)),""barcelona""), ""acc_139"", REGEXMATCH(LOWER(TRIM(U16)),""madrid""), ""acc_148"", REGEXMATCH(LOWER(TRIM(U16)),""zaragoza""), ""acc_149"", REGEXMATCH(LOWER(TRIM(U16)),""ibiza""), ""acc_140"", REGEXMATCH(LOWER(TRI"&"M(U16)),""mallorca""), ""acc_140"", REGEXMATCH(LOWER(TRIM(U16)),""menorca""), ""acc_150"", TRUE, """" ) "),"acc_148") -> acc_148 | I16: Ana | K16: Placement | L16: =IFERROR(__xludf.DUMMYFUNCTION("LET( s, UPPER(TRIM(T16)), IF(REGEXMATCH(s,""CLOSED.*WON""), ""ACTIVA"", IF(REGEXMATCH(s,""CLOSED.*LOST""), ""FALLIDA"", IF(REGEXMATCH(s,""CONTACT.*NEXT.*SEASON""), ""POTENCIAL"", IF(REGEXMATCH(s,""\bLEAD\b""), ""LEAD"", IF(REGEXMATCH(s,""INTER"&"EST|POTENTIAL""), ""SEGUIMIENTO"", ""SEGUIMIENTO""))))) ) "),"ACTIVA") -> ACTIVA | N16: =V16 -> Nico | O16: =W16 | S16: FALSE | T16: CLOSED / WON | U16: Madrid | V16: Nico
A17: acc_016 | B17: Cervecería Santa Barbara | C17: =IFERROR(__xludf.DUMMYFUNCTION("IFS( REGEXMATCH(LOWER(TRIM(N17)),""nico""), ""us_001"", REGEXMATCH(LOWER(TRIM(N17)),""alfonso""), ""us_002"", REGEXMATCH(LOWER(TRIM(N17)),""patxi""), ""us_003"", REGEXMATCH(LOWER(TRIM(N17)),""martin""), ""us_004"", TRUE, ""us_999"" )"),"us_002") -> us_002 | D17: =IFERROR(__xludf.DUMMYFUNCTION("""COMPUTED_VALUE"""),"us_002") -> us_002 | E17: Horeca | F17: =IFERROR(__xludf.DUMMYFUNCTION("LET( s, UPPER(TRIM(N17)), IF(REGEXMATCH(s,""CLOSED.*WON""), ""ACTIVA"", IF(REGEXMATCH(s,""CLOSED.*LOST""), ""FALLIDA"", IF(REGEXMATCH(s,""CONTACT.*NEXT.*SEASON""), ""POTENCIAL"", IF(REGEXMATCH(s,""\bLEAD\b""), ""LEAD"", IF(REGEXMATCH(s,""INTER"&"EST|POTENTIAL""), ""SEGUIMIENTO"", ""SEGUIMIENTO""))))) ) "),"SEGUIMIENTO") -> SEGUIMIENTO | G17: Placement | H17: =IFERROR(__xludf.DUMMYFUNCTION("IFS( REGEXMATCH(LOWER(TRIM(U17)),""barcelona""), ""acc_139"", REGEXMATCH(LOWER(TRIM(U17)),""madrid""), ""acc_148"", REGEXMATCH(LOWER(TRIM(U17)),""zaragoza""), ""acc_149"", REGEXMATCH(LOWER(TRIM(U17)),""ibiza""), ""acc_140"", REGEXMATCH(LOWER(TRI"&"M(U17)),""mallorca""), ""acc_140"", REGEXMATCH(LOWER(TRIM(U17)),""menorca""), ""acc_150"", TRUE, """" ) "),"acc_148") -> acc_148 | I17: Álvaro | K17: Placement | L17: =IFERROR(__xludf.DUMMYFUNCTION("LET( s, UPPER(TRIM(T17)), IF(REGEXMATCH(s,""CLOSED.*WON""), ""ACTIVA"", IF(REGEXMATCH(s,""CLOSED.*LOST""), ""FALLIDA"", IF(REGEXMATCH(s,""CONTACT.*NEXT.*SEASON""), ""POTENCIAL"", IF(REGEXMATCH(s,""\bLEAD\b""), ""LEAD"", IF(REGEXMATCH(s,""INTER"&"EST|POTENTIAL""), ""SEGUIMIENTO"", ""SEGUIMIENTO""))))) ) "),"ACTIVA") -> ACTIVA | N17: =V17 -> Alfonso | O17: =W17 | S17: FALSE | T17: CLOSED / WON | U17: Madrid | V17: Alfonso | Y17: 10 vasos
A18: acc_017 | B18: Catering the cook | C18: =IFERROR(__xludf.DUMMYFUNCTION("IFS( REGEXMATCH(LOWER(TRIM(N18)),""nico""), ""us_001"", REGEXMATCH(LOWER(TRIM(N18)),""alfonso""), ""us_002"", REGEXMATCH(LOWER(TRIM(N18)),""patxi""), ""us_003"", REGEXMATCH(LOWER(TRIM(N18)),""martin""), ""us_004"", TRUE, ""us_999"" )"),"us_002") -> us_002 | D18: =IFERROR(__xludf.DUMMYFUNCTION("""COMPUTED_VALUE"""),"us_002") -> us_002 | E18: Horeca | F18: =IFERROR(__xludf.DUMMYFUNCTION("LET( s, UPPER(TRIM(N18)), IF(REGEXMATCH(s,""CLOSED.*WON""), ""ACTIVA"", IF(REGEXMATCH(s,""CLOSED.*LOST""), ""FALLIDA"", IF(REGEXMATCH(s,""CONTACT.*NEXT.*SEASON""), ""POTENCIAL"", IF(REGEXMATCH(s,""\bLEAD\b""), ""LEAD"", IF(REGEXMATCH(s,""INTER"&"EST|POTENTIAL""), ""SEGUIMIENTO"", ""SEGUIMIENTO""))))) ) "),"SEGUIMIENTO") -> SEGUIMIENTO | G18: Placement | H18: =IFERROR(__xludf.DUMMYFUNCTION("IFS( REGEXMATCH(LOWER(TRIM(U18)),""barcelona""), ""acc_139"", REGEXMATCH(LOWER(TRIM(U18)),""madrid""), ""acc_148"", REGEXMATCH(LOWER(TRIM(U18)),""zaragoza""), ""acc_149"", REGEXMATCH(LOWER(TRIM(U18)),""ibiza""), ""acc_140"", REGEXMATCH(LOWER(TRI"&"M(U18)),""mallorca""), ""acc_140"", REGEXMATCH(LOWER(TRIM(U18)),""menorca""), ""acc_150"", TRUE, """" ) "),"acc_148") -> acc_148 | I18: Silvia Lodares | K18: Placement | L18: =IFERROR(__xludf.DUMMYFUNCTION("LET( s, UPPER(TRIM(T18)), IF(REGEXMATCH(s,""CLOSED.*WON""), ""ACTIVA"", IF(REGEXMATCH(s,""CLOSED.*LOST""), ""FALLIDA"", IF(REGEXMATCH(s,""CONTACT.*NEXT.*SEASON""), ""POTENCIAL"", IF(REGEXMATCH(s,""\bLEAD\b""), ""LEAD"", IF(REGEXMATCH(s,""INTER"&"EST|POTENTIAL""), ""SEGUIMIENTO"", ""SEGUIMIENTO""))))) ) "),"ACTIVA") -> ACTIVA | N18: =V18 -> Alfonso | O18: =W18 | S18: FALSE | T18: CLOSED / WON | U18: Madrid | V18: Alfonso
A19: acc_018 | B19: Bulo | C19: =IFERROR(__xludf.DUMMYFUNCTION("IFS( REGEXMATCH(LOWER(TRIM(N19)),""nico""), ""us_001"", REGEXMATCH(LOWER(TRIM(N19)),""alfonso""), ""us_002"", REGEXMATCH(LOWER(TRIM(N19)),""patxi""), ""us_003"", REGEXMATCH(LOWER(TRIM(N19)),""martin""), ""us_004"", TRUE, ""us_999"" )"),"us_002") -> us_002 | D19: =IFERROR(__xludf.DUMMYFUNCTION("""COMPUTED_VALUE"""),"us_002") -> us_002 | E19: Horeca | F19: =IFERROR(__xludf.DUMMYFUNCTION("LET( s, UPPER(TRIM(N19)), IF(REGEXMATCH(s,""CLOSED.*WON""), ""ACTIVA"", IF(REGEXMATCH(s,""CLOSED.*LOST""), ""FALLIDA"", IF(REGEXMATCH(s,""CONTACT.*NEXT.*SEASON""), ""POTENCIAL"", IF(REGEXMATCH(s,""\bLEAD\b""), ""LEAD"", IF(REGEXMATCH(s,""INTER"&"EST|POTENTIAL""), ""SEGUIMIENTO"", ""SEGUIMIENTO""))))) ) "),"SEGUIMIENTO") -> SEGUIMIENTO | G19: Placement | H19: =IFERROR(__xludf.DUMMYFUNCTION("IFS( REGEXMATCH(LOWER(TRIM(U19)),""barcelona""), ""acc_139"", REGEXMATCH(LOWER(TRIM(U19)),""madrid""), ""acc_148"", REGEXMATCH(LOWER(TRIM(U19)),""zaragoza""), ""acc_149"", REGEXMATCH(LOWER(TRIM(U19)),""ibiza""), ""acc_140"", REGEXMATCH(LOWER(TRI"&"M(U19)),""mallorca""), ""acc_140"", REGEXMATCH(LOWER(TRIM(U19)),""menorca""), ""acc_150"", TRUE, """" ) "),"acc_148") -> acc_148 | I19: Manu Cabello | K19: Placement | L19: =IFERROR(__xludf.DUMMYFUNCTION("LET( s, UPPER(TRIM(T19)), IF(REGEXMATCH(s,""CLOSED.*WON""), ""ACTIVA"", IF(REGEXMATCH(s,""CLOSED.*LOST""), ""FALLIDA"", IF(REGEXMATCH(s,""CONTACT.*NEXT.*SEASON""), ""POTENCIAL"", IF(REGEXMATCH(s,""\bLEAD\b""), ""LEAD"", IF(REGEXMATCH(s,""INTER"&"EST|POTENTIAL""), ""SEGUIMIENTO"", ""SEGUIMIENTO""))))) ) "),"ACTIVA") -> ACTIVA | N19: =V19 -> Alfonso | O19: =W19 | S19: FALSE | T19: CLOSED / WON | U19: Madrid | V19: Alfonso
A20: acc_019 | B20: Joselito | C20: =IFERROR(__xludf.DUMMYFUNCTION("IFS( REGEXMATCH(LOWER(TRIM(N20)),""nico""), ""us_001"", REGEXMATCH(LOWER(TRIM(N20)),""alfonso""), ""us_002"", REGEXMATCH(LOWER(TRIM(N20)),""patxi""), ""us_003"", REGEXMATCH(LOWER(TRIM(N20)),""martin""), ""us_004"", TRUE, ""us_999"" )"),"us_001") -> us_001 | D20: =IFERROR(__xludf.DUMMYFUNCTION("""COMPUTED_VALUE"""),"us_001") -> us_001 | E20: Horeca | F20: =IFERROR(__xludf.DUMMYFUNCTION("LET( s, UPPER(TRIM(N20)), IF(REGEXMATCH(s,""CLOSED.*WON""), ""ACTIVA"", IF(REGEXMATCH(s,""CLOSED.*LOST""), ""FALLIDA"", IF(REGEXMATCH(s,""CONTACT.*NEXT.*SEASON""), ""POTENCIAL"", IF(REGEXMATCH(s,""\bLEAD\b""), ""LEAD"", IF(REGEXMATCH(s,""INTER"&"EST|POTENTIAL""), ""SEGUIMIENTO"", ""SEGUIMIENTO""))))) ) "),"SEGUIMIENTO") -> SEGUIMIENTO | G20: Placement | H20: =IFERROR(__xludf.DUMMYFUNCTION("IFS( REGEXMATCH(LOWER(TRIM(U20)),""barcelona""), ""acc_139"", REGEXMATCH(LOWER(TRIM(U20)),""madrid""), ""acc_148"", REGEXMATCH(LOWER(TRIM(U20)),""zaragoza""), ""acc_149"", REGEXMATCH(LOWER(TRIM(U20)),""ibiza""), ""acc_140"", REGEXMATCH(LOWER(TRI"&"M(U20)),""mallorca""), ""acc_140"", REGEXMATCH(LOWER(TRIM(U20)),""menorca""), ""acc_150"", TRUE, """" ) "),"acc_148") -> acc_148 | I20: Carlos y jose Gómez | K20: Placement | L20: =IFERROR(__xludf.DUMMYFUNCTION("LET( s, UPPER(TRIM(T20)), IF(REGEXMATCH(s,""CLOSED.*WON""), ""ACTIVA"", IF(REGEXMATCH(s,""CLOSED.*LOST""), ""FALLIDA"", IF(REGEXMATCH(s,""CONTACT.*NEXT.*SEASON""), ""POTENCIAL"", IF(REGEXMATCH(s,""\bLEAD\b""), ""LEAD"", IF(REGEXMATCH(s,""INTER"&"EST|POTENTIAL""), ""SEGUIMIENTO"", ""SEGUIMIENTO""))))) ) "),"ACTIVA") -> ACTIVA | N20: =V20 -> Nico | O20: =W20 | S20: FALSE | T20: CLOSED / WON | U20: Madrid | V20: Nico
A21: acc_020 | B21: Adrede | C21: =IFERROR(__xludf.DUMMYFUNCTION("IFS( REGEXMATCH(LOWER(TRIM(N21)),""nico""), ""us_001"", REGEXMATCH(LOWER(TRIM(N21)),""alfonso""), ""us_002"", REGEXMATCH(LOWER(TRIM(N21)),""patxi""), ""us_003"", REGEXMATCH(LOWER(TRIM(N21)),""martin""), ""us_004"", TRUE, ""us_999"" )"),"us_001") -> us_001 | D21: =IFERROR(__xludf.DUMMYFUNCTION("""COMPUTED_VALUE"""),"us_001") -> us_001 | E21: Horeca | F21: =IFERROR(__xludf.DUMMYFUNCTION("LET( s, UPPER(TRIM(N21)), IF(REGEXMATCH(s,""CLOSED.*WON""), ""ACTIVA"", IF(REGEXMATCH(s,""CLOSED.*LOST""), ""FALLIDA"", IF(REGEXMATCH(s,""CONTACT.*NEXT.*SEASON""), ""POTENCIAL"", IF(REGEXMATCH(s,""\bLEAD\b""), ""LEAD"", IF(REGEXMATCH(s,""INTER"&"EST|POTENTIAL""), ""SEGUIMIENTO"", ""SEGUIMIENTO""))))) ) "),"SEGUIMIENTO") -> SEGUIMIENTO | G21: Placement | H21: =IFERROR(__xludf.DUMMYFUNCTION("IFS( REGEXMATCH(LOWER(TRIM(U21)),""barcelona""), ""acc_139"", REGEXMATCH(LOWER(TRIM(U21)),""madrid""), ""acc_148"", REGEXMATCH(LOWER(TRIM(U21)),""zaragoza""), ""acc_149"", REGEXMATCH(LOWER(TRIM(U21)),""ibiza""), ""acc_140"", REGEXMATCH(LOWER(TRI"&"M(U21)),""mallorca""), ""acc_140"", REGEXMATCH(LOWER(TRIM(U21)),""menorca""), ""acc_150"", TRUE, """" ) "),"acc_148") -> acc_148 | I21: Angel | K21: Placement | L21: =IFERROR(__xludf.DUMMYFUNCTION("LET( s, UPPER(TRIM(T21)), IF(REGEXMATCH(s,""CLOSED.*WON""), ""ACTIVA"", IF(REGEXMATCH(s,""CLOSED.*LOST""), ""FALLIDA"", IF(REGEXMATCH(s,""CONTACT.*NEXT.*SEASON""), ""POTENCIAL"", IF(REGEXMATCH(s,""\bLEAD\b""), ""LEAD"", IF(REGEXMATCH(s,""INTER"&"EST|POTENTIAL""), ""SEGUIMIENTO"", ""SEGUIMIENTO""))))) ) "),"ACTIVA") -> ACTIVA | N21: =V21 -> Nico | O21: =W21 | S21: FALSE | T21: CLOSED / WON | U21: Madrid | V21: Nico
A22: acc_021 | B22: Las tablas | C22: =IFERROR(__xludf.DUMMYFUNCTION("IFS( REGEXMATCH(LOWER(TRIM(N22)),""nico""), ""us_001"", REGEXMATCH(LOWER(TRIM(N22)),""alfonso""), ""us_002"", REGEXMATCH(LOWER(TRIM(N22)),""patxi""), ""us_003"", REGEXMATCH(LOWER(TRIM(N22)),""martin""), ""us_004"", TRUE, ""us_999"" )"),"us_002") -> us_002 | D22: =IFERROR(__xludf.DUMMYFUNCTION("""COMPUTED_VALUE"""),"us_002") -> us_002 | E22: Horeca | F22: =IFERROR(__xludf.DUMMYFUNCTION("LET( s, UPPER(TRIM(N22)), IF(REGEXMATCH(s,""CLOSED.*WON""), ""ACTIVA"", IF(REGEXMATCH(s,""CLOSED.*LOST""), ""FALLIDA"", IF(REGEXMATCH(s,""CONTACT.*NEXT.*SEASON""), ""POTENCIAL"", IF(REGEXMATCH(s,""\bLEAD\b""), ""LEAD"", IF(REGEXMATCH(s,""INTER"&"EST|POTENTIAL""), ""SEGUIMIENTO"", ""SEGUIMIENTO""))))) ) "),"SEGUIMIENTO") -> SEGUIMIENTO | G22: Placement | H22: =IFERROR(__xludf.DUMMYFUNCTION("IFS( REGEXMATCH(LOWER(TRIM(U22)),""barcelona""), ""acc_139"", REGEXMATCH(LOWER(TRIM(U22)),""madrid""), ""acc_148"", REGEXMATCH(LOWER(TRIM(U22)),""zaragoza""), ""acc_149"", REGEXMATCH(LOWER(TRIM(U22)),""ibiza""), ""acc_140"", REGEXMATCH(LOWER(TRI"&"M(U22)),""mallorca""), ""acc_140"", REGEXMATCH(LOWER(TRIM(U22)),""menorca""), ""acc_150"", TRUE, """" ) "),"acc_148") -> acc_148 | I22: Borja | K22: Placement | L22: =IFERROR(__xludf.DUMMYFUNCTION("LET( s, UPPER(TRIM(T22)), IF(REGEXMATCH(s,""CLOSED.*WON""), ""ACTIVA"", IF(REGEXMATCH(s,""CLOSED.*LOST""), ""FALLIDA"", IF(REGEXMATCH(s,""CONTACT.*NEXT.*SEASON""), ""POTENCIAL"", IF(REGEXMATCH(s,""\bLEAD\b""), ""LEAD"", IF(REGEXMATCH(s,""INTER"&"EST|POTENTIAL""), ""SEGUIMIENTO"", ""SEGUIMIENTO""))))) ) "),"ACTIVA") -> ACTIVA | N22: =V22 -> Alfonso | O22: =W22 | S22: FALSE | T22: CLOSED / WON | U22: Madrid | V22: Alfonso
A23: acc_022 | B23: Gabys Bagels | C23: =IFERROR(__xludf.DUMMYFUNCTION("IFS( REGEXMATCH(LOWER(TRIM(N23)),""nico""), ""us_001"", REGEXMATCH(LOWER(TRIM(N23)),""alfonso""), ""us_002"", REGEXMATCH(LOWER(TRIM(N23)),""patxi""), ""us_003"", REGEXMATCH(LOWER(TRIM(N23)),""martin""), ""us_004"", TRUE, ""us_999"" )"),"us_002") -> us_002 | D23: =IFERROR(__xludf.DUMMYFUNCTION("""COMPUTED_VALUE"""),"us_002") -> us_002 | E23: Horeca | F23: =IFERROR(__xludf.DUMMYFUNCTION("LET( s, UPPER(TRIM(N23)), IF(REGEXMATCH(s,""CLOSED.*WON""), ""ACTIVA"", IF(REGEXMATCH(s,""CLOSED.*LOST""), ""FALLIDA"", IF(REGEXMATCH(s,""CONTACT.*NEXT.*SEASON""), ""POTENCIAL"", IF(REGEXMATCH(s,""\bLEAD\b""), ""LEAD"", IF(REGEXMATCH(s,""INTER"&"EST|POTENTIAL""), ""SEGUIMIENTO"", ""SEGUIMIENTO""))))) ) "),"SEGUIMIENTO") -> SEGUIMIENTO | G23: Placement | H23: =IFERROR(__xludf.DUMMYFUNCTION("IFS( REGEXMATCH(LOWER(TRIM(U23)),""barcelona""), ""acc_139"", REGEXMATCH(LOWER(TRIM(U23)),""madrid""), ""acc_148"", REGEXMATCH(LOWER(TRIM(U23)),""zaragoza""), ""acc_149"", REGEXMATCH(LOWER(TRIM(U23)),""ibiza""), ""acc_140"", REGEXMATCH(LOWER(TRI"&"M(U23)),""mallorca""), ""acc_140"", REGEXMATCH(LOWER(TRIM(U23)),""menorca""), ""acc_150"", TRUE, """" ) "),"acc_148") -> acc_148 | I23: Baby y Rafa | K23: Placement | L23: =IFERROR(__xludf.DUMMYFUNCTION("LET( s, UPPER(TRIM(T23)), IF(REGEXMATCH(s,""CLOSED.*WON""), ""ACTIVA"", IF(REGEXMATCH(s,""CLOSED.*LOST""), ""FALLIDA"", IF(REGEXMATCH(s,""CONTACT.*NEXT.*SEASON""), ""POTENCIAL"", IF(REGEXMATCH(s,""\bLEAD\b""), ""LEAD"", IF(REGEXMATCH(s,""INTER"&"EST|POTENTIAL""), ""SEGUIMIENTO"", ""SEGUIMIENTO""))))) ) "),"ACTIVA") -> ACTIVA | N23: =V23 -> Alfonso | O23: =W23 | S23: FALSE | T23: CLOSED / WON | U23: Madrid | V23: Alfonso
A24: acc_023 | B24: Delirium | C24: =IFERROR(__xludf.DUMMYFUNCTION("IFS( REGEXMATCH(LOWER(TRIM(N24)),""nico""), ""us_001"", REGEXMATCH(LOWER(TRIM(N24)),""alfonso""), ""us_002"", REGEXMATCH(LOWER(TRIM(N24)),""patxi""), ""us_003"", REGEXMATCH(LOWER(TRIM(N24)),""martin""), ""us_004"", TRUE, ""us_999"" )"),"us_002") -> us_002 | D24: =IFERROR(__xludf.DUMMYFUNCTION("""COMPUTED_VALUE"""),"us_002") -> us_002 | E24: Horeca | F24: =IFERROR(__xludf.DUMMYFUNCTION("LET( s, UPPER(TRIM(N24)), IF(REGEXMATCH(s,""CLOSED.*WON""), ""ACTIVA"", IF(REGEXMATCH(s,""CLOSED.*LOST""), ""FALLIDA"", IF(REGEXMATCH(s,""CONTACT.*NEXT.*SEASON""), ""POTENCIAL"", IF(REGEXMATCH(s,""\bLEAD\b""), ""LEAD"", IF(REGEXMATCH(s,""INTER"&"EST|POTENTIAL""), ""SEGUIMIENTO"", ""SEGUIMIENTO""))))) ) "),"SEGUIMIENTO") -> SEGUIMIENTO | G24: Placement | H24: =IFERROR(__xludf.DUMMYFUNCTION("IFS( REGEXMATCH(LOWER(TRIM(U24)),""barcelona""), ""acc_139"", REGEXMATCH(LOWER(TRIM(U24)),""madrid""), ""acc_148"", REGEXMATCH(LOWER(TRIM(U24)),""zaragoza""), ""acc_149"", REGEXMATCH(LOWER(TRIM(U24)),""ibiza""), ""acc_140"", REGEXMATCH(LOWER(TRI"&"M(U24)),""mallorca""), ""acc_140"", REGEXMATCH(LOWER(TRIM(U24)),""menorca""), ""acc_150"", TRUE, """" ) "),"acc_148") -> acc_148 | I24: Lu | K24: Placement | L24: =IFERROR(__xludf.DUMMYFUNCTION("LET( s, UPPER(TRIM(T24)), IF(REGEXMATCH(s,""CLOSED.*WON""), ""ACTIVA"", IF(REGEXMATCH(s,""CLOSED.*LOST""), ""FALLIDA"", IF(REGEXMATCH(s,""CONTACT.*NEXT.*SEASON""), ""POTENCIAL"", IF(REGEXMATCH(s,""\bLEAD\b""), ""LEAD"", IF(REGEXMATCH(s,""INTER"&"EST|POTENTIAL""), ""SEGUIMIENTO"", ""SEGUIMIENTO""))))) ) "),"ACTIVA") -> ACTIVA | N24: =V24 -> Alfonso | O24: =W24 | S24: FALSE | T24: CLOSED / WON | U24: Madrid | V24: Alfonso
A25: acc_024 | B25: Terraza campo del moro | C25: =IFERROR(__xludf.DUMMYFUNCTION("IFS( REGEXMATCH(LOWER(TRIM(N25)),""nico""), ""us_001"", REGEXMATCH(LOWER(TRIM(N25)),""alfonso""), ""us_002"", REGEXMATCH(LOWER(TRIM(N25)),""patxi""), ""us_003"", REGEXMATCH(LOWER(TRIM(N25)),""martin""), ""us_004"", TRUE, ""us_999"" )"),"us_002") -> us_002 | D25: =IFERROR(__xludf.DUMMYFUNCTION("""COMPUTED_VALUE"""),"us_002") -> us_002 | E25: Horeca | F25: =IFERROR(__xludf.DUMMYFUNCTION("LET( s, UPPER(TRIM(N25)), IF(REGEXMATCH(s,""CLOSED.*WON""), ""ACTIVA"", IF(REGEXMATCH(s,""CLOSED.*LOST""), ""FALLIDA"", IF(REGEXMATCH(s,""CONTACT.*NEXT.*SEASON""), ""POTENCIAL"", IF(REGEXMATCH(s,""\bLEAD\b""), ""LEAD"", IF(REGEXMATCH(s,""INTER"&"EST|POTENTIAL""), ""SEGUIMIENTO"", ""SEGUIMIENTO""))))) ) "),"SEGUIMIENTO") -> SEGUIMIENTO | G25: Placement | H25: =IFERROR(__xludf.DUMMYFUNCTION("IFS( REGEXMATCH(LOWER(TRIM(U25)),""barcelona""), ""acc_139"", REGEXMATCH(LOWER(TRIM(U25)),""madrid""), ""acc_148"", REGEXMATCH(LOWER(TRIM(U25)),""zaragoza""), ""acc_149"", REGEXMATCH(LOWER(TRIM(U25)),""ibiza""), ""acc_140"", REGEXMATCH(LOWER(TRI"&"M(U25)),""mallorca""), ""acc_140"", REGEXMATCH(LOWER(TRIM(U25)),""menorca""), ""acc_150"", TRUE, """" ) "),"acc_148") -> acc_148 | I25: Luna | K25: Placement | L25: =IFERROR(__xludf.DUMMYFUNCTION("LET( s, UPPER(TRIM(T25)), IF(REGEXMATCH(s,""CLOSED.*WON""), ""ACTIVA"", IF(REGEXMATCH(s,""CLOSED.*LOST""), ""FALLIDA"", IF(REGEXMATCH(s,""CONTACT.*NEXT.*SEASON""), ""POTENCIAL"", IF(REGEXMATCH(s,""\bLEAD\b""), ""LEAD"", IF(REGEXMATCH(s,""INTER"&"EST|POTENTIAL""), ""SEGUIMIENTO"", ""SEGUIMIENTO""))))) ) "),"ACTIVA") -> ACTIVA | N25: =V25 -> Alfonso | O25: =W25 -> 4 cajas | S25: FALSE | T25: CLOSED / WON | U25: Madrid | V25: Alfonso | W25: 4 cajas
A26: acc_025 | B26: Abacería Macarena | C26: =IFERROR(__xludf.DUMMYFUNCTION("IFS( REGEXMATCH(LOWER(TRIM(N26)),""nico""), ""us_001"", REGEXMATCH(LOWER(TRIM(N26)),""alfonso""), ""us_002"", REGEXMATCH(LOWER(TRIM(N26)),""patxi""), ""us_003"", REGEXMATCH(LOWER(TRIM(N26)),""martin""), ""us_004"", TRUE, ""us_999"" )"),"us_002") -> us_002 | D26: =IFERROR(__xludf.DUMMYFUNCTION("""COMPUTED_VALUE"""),"us_002") -> us_002 | E26: Horeca | F26: =IFERROR(__xludf.DUMMYFUNCTION("LET( s, UPPER(TRIM(N26)), IF(REGEXMATCH(s,""CLOSED.*WON""), ""ACTIVA"", IF(REGEXMATCH(s,""CLOSED.*LOST""), ""FALLIDA"", IF(REGEXMATCH(s,""CONTACT.*NEXT.*SEASON""), ""POTENCIAL"", IF(REGEXMATCH(s,""\bLEAD\b""), ""LEAD"", IF(REGEXMATCH(s,""INTER"&"EST|POTENTIAL""), ""SEGUIMIENTO"", ""SEGUIMIENTO""))))) ) "),"SEGUIMIENTO") -> SEGUIMIENTO | G26: Placement | H26: =IFERROR(__xludf.DUMMYFUNCTION("IFS( REGEXMATCH(LOWER(TRIM(U26)),""barcelona""), ""acc_139"", REGEXMATCH(LOWER(TRIM(U26)),""madrid""), ""acc_148"", REGEXMATCH(LOWER(TRIM(U26)),""zaragoza""), ""acc_149"", REGEXMATCH(LOWER(TRIM(U26)),""ibiza""), ""acc_140"", REGEXMATCH(LOWER(TRI"&"M(U26)),""mallorca""), ""acc_140"", REGEXMATCH(LOWER(TRIM(U26)),""menorca""), ""acc_150"", TRUE, """" ) "),"acc_148") -> acc_148 | I26: Luis Magaña | K26: Placement | L26: =IFERROR(__xludf.DUMMYFUNCTION("LET( s, UPPER(TRIM(T26)), IF(REGEXMATCH(s,""CLOSED.*WON""), ""ACTIVA"", IF(REGEXMATCH(s,""CLOSED.*LOST""), ""FALLIDA"", IF(REGEXMATCH(s,""CONTACT.*NEXT.*SEASON""), ""POTENCIAL"", IF(REGEXMATCH(s,""\bLEAD\b""), ""LEAD"", IF(REGEXMATCH(s,""INTER"&"EST|POTENTIAL""), ""SEGUIMIENTO"", ""SEGUIMIENTO""))))) ) "),"ACTIVA") -> ACTIVA | N26: =V26 -> Alfonso | O26: =W26 | S26: FALSE | T26: CLOSED / WON | U26: Madrid | V26: Alfonso
A27: acc_026 | B27: Cockatil Bar 1885 | C27: =IFERROR(__xludf.DUMMYFUNCTION("IFS( REGEXMATCH(LOWER(TRIM(N27)),""nico""), ""us_001"", REGEXMATCH(LOWER(TRIM(N27)),""alfonso""), ""us_002"", REGEXMATCH(LOWER(TRIM(N27)),""patxi""), ""us_003"", REGEXMATCH(LOWER(TRIM(N27)),""martin""), ""us_004"", TRUE, ""us_999"" )"),"us_001") -> us_001 | D27: =IFERROR(__xludf.DUMMYFUNCTION("""COMPUTED_VALUE"""),"us_001") -> us_001 | E27: Horeca | F27: =IFERROR(__xludf.DUMMYFUNCTION("LET( s, UPPER(TRIM(N27)), IF(REGEXMATCH(s,""CLOSED.*WON""), ""ACTIVA"", IF(REGEXMATCH(s,""CLOSED.*LOST""), ""FALLIDA"", IF(REGEXMATCH(s,""CONTACT.*NEXT.*SEASON""), ""POTENCIAL"", IF(REGEXMATCH(s,""\bLEAD\b""), ""LEAD"", IF(REGEXMATCH(s,""INTER"&"EST|POTENTIAL""), ""SEGUIMIENTO"", ""SEGUIMIENTO""))))) ) "),"SEGUIMIENTO") -> SEGUIMIENTO | G27: Placement | H27: =IFERROR(__xludf.DUMMYFUNCTION("IFS( REGEXMATCH(LOWER(TRIM(U27)),""barcelona""), ""acc_139"", REGEXMATCH(LOWER(TRIM(U27)),""madrid""), ""acc_148"", REGEXMATCH(LOWER(TRIM(U27)),""zaragoza""), ""acc_149"", REGEXMATCH(LOWER(TRIM(U27)),""ibiza""), ""acc_140"", REGEXMATCH(LOWER(TRI"&"M(U27)),""mallorca""), ""acc_140"", REGEXMATCH(LOWER(TRIM(U27)),""menorca""), ""acc_150"", TRUE, """" ) "),"acc_149") -> acc_149 | K27: Placement | L27: =IFERROR(__xludf.DUMMYFUNCTION("LET( s, UPPER(TRIM(T27)), IF(REGEXMATCH(s,""CLOSED.*WON""), ""ACTIVA"", IF(REGEXMATCH(s,""CLOSED.*LOST""), ""FALLIDA"", IF(REGEXMATCH(s,""CONTACT.*NEXT.*SEASON""), ""POTENCIAL"", IF(REGEXMATCH(s,""\bLEAD\b""), ""LEAD"", IF(REGEXMATCH(s,""INTER"&"EST|POTENTIAL""), ""SEGUIMIENTO"", ""SEGUIMIENTO""))))) ) "),"ACTIVA") -> ACTIVA | N27: =V27 -> Nico | O27: =W27 | S27: FALSE | T27: CLOSED / WON | U27: Zaragoza | V27: Nico
A28: acc_027 | B28: La embajada | C28: =IFERROR(__xludf.DUMMYFUNCTION("IFS( REGEXMATCH(LOWER(TRIM(N28)),""nico""), ""us_001"", REGEXMATCH(LOWER(TRIM(N28)),""alfonso""), ""us_002"", REGEXMATCH(LOWER(TRIM(N28)),""patxi""), ""us_003"", REGEXMATCH(LOWER(TRIM(N28)),""martin""), ""us_004"", TRUE, ""us_999"" )"),"us_001") -> us_001 | D28: =IFERROR(__xludf.DUMMYFUNCTION("""COMPUTED_VALUE"""),"us_001") -> us_001 | E28: Horeca | F28: =IFERROR(__xludf.DUMMYFUNCTION("LET( s, UPPER(TRIM(N28)), IF(REGEXMATCH(s,""CLOSED.*WON""), ""ACTIVA"", IF(REGEXMATCH(s,""CLOSED.*LOST""), ""FALLIDA"", IF(REGEXMATCH(s,""CONTACT.*NEXT.*SEASON""), ""POTENCIAL"", IF(REGEXMATCH(s,""\bLEAD\b""), ""LEAD"", IF(REGEXMATCH(s,""INTER"&"EST|POTENTIAL""), ""SEGUIMIENTO"", ""SEGUIMIENTO""))))) ) "),"SEGUIMIENTO") -> SEGUIMIENTO | G28: Placement | H28: =IFERROR(__xludf.DUMMYFUNCTION("IFS( REGEXMATCH(LOWER(TRIM(U28)),""barcelona""), ""acc_139"", REGEXMATCH(LOWER(TRIM(U28)),""madrid""), ""acc_148"", REGEXMATCH(LOWER(TRIM(U28)),""zaragoza""), ""acc_149"", REGEXMATCH(LOWER(TRIM(U28)),""ibiza""), ""acc_140"", REGEXMATCH(LOWER(TRI"&"M(U28)),""mallorca""), ""acc_140"", REGEXMATCH(LOWER(TRIM(U28)),""menorca""), ""acc_150"", TRUE, """" ) "),"acc_149") -> acc_149 | K28: Placement | L28: =IFERROR(__xludf.DUMMYFUNCTION("LET( s, UPPER(TRIM(T28)), IF(REGEXMATCH(s,""CLOSED.*WON""), ""ACTIVA"", IF(REGEXMATCH(s,""CLOSED.*LOST""), ""FALLIDA"", IF(REGEXMATCH(s,""CONTACT.*NEXT.*SEASON""), ""POTENCIAL"", IF(REGEXMATCH(s,""\bLEAD\b""), ""LEAD"", IF(REGEXMATCH(s,""INTER"&"EST|POTENTIAL""), ""SEGUIMIENTO"", ""SEGUIMIENTO""))))) ) "),"ACTIVA") -> ACTIVA | N28: =V28 -> Nico | O28: =W28 -> 4 cajas | S28: FALSE | T28: CLOSED / WON | U28: Zaragoza | V28: Nico | W28: 4 cajas
A29: acc_028 | B29: Tiare Beach Club | C29: =IFERROR(__xludf.DUMMYFUNCTION("IFS( REGEXMATCH(LOWER(TRIM(N29)),""nico""), ""us_001"", REGEXMATCH(LOWER(TRIM(N29)),""alfonso""), ""us_002"", REGEXMATCH(LOWER(TRIM(N29)),""patxi""), ""us_003"", REGEXMATCH(LOWER(TRIM(N29)),""martin""), ""us_004"", TRUE, ""us_999"" )"),"us_003") -> us_003 | D29: =IFERROR(__xludf.DUMMYFUNCTION("""COMPUTED_VALUE"""),"us_003") -> us_003 | E29: Horeca | F29: =IFERROR(__xludf.DUMMYFUNCTION("LET( s, UPPER(TRIM(N29)), IF(REGEXMATCH(s,""CLOSED.*WON""), ""ACTIVA"", IF(REGEXMATCH(s,""CLOSED.*LOST""), ""FALLIDA"", IF(REGEXMATCH(s,""CONTACT.*NEXT.*SEASON""), ""POTENCIAL"", IF(REGEXMATCH(s,""\bLEAD\b""), ""LEAD"", IF(REGEXMATCH(s,""INTER"&"EST|POTENTIAL""), ""SEGUIMIENTO"", ""SEGUIMIENTO""))))) ) "),"SEGUIMIENTO") -> SEGUIMIENTO | G29: Placement | H29: =IFERROR(__xludf.DUMMYFUNCTION("IFS( REGEXMATCH(LOWER(TRIM(U29)),""barcelona""), ""acc_139"", REGEXMATCH(LOWER(TRIM(U29)),""madrid""), ""acc_148"", REGEXMATCH(LOWER(TRIM(U29)),""zaragoza""), ""acc_149"", REGEXMATCH(LOWER(TRIM(U29)),""ibiza""), ""acc_140"", REGEXMATCH(LOWER(TRI"&"M(U29)),""mallorca""), ""acc_140"", REGEXMATCH(LOWER(TRIM(U29)),""menorca""), ""acc_150"", TRUE, """" ) "),"") | K29: Placement | L29: =IFERROR(__xludf.DUMMYFUNCTION("LET( s, UPPER(TRIM(T29)), IF(REGEXMATCH(s,""CLOSED.*WON""), ""ACTIVA"", IF(REGEXMATCH(s,""CLOSED.*LOST""), ""FALLIDA"", IF(REGEXMATCH(s,""CONTACT.*NEXT.*SEASON""), ""POTENCIAL"", IF(REGEXMATCH(s,""\bLEAD\b""), ""LEAD"", IF(REGEXMATCH(s,""INTER"&"EST|POTENTIAL""), ""SEGUIMIENTO"", ""SEGUIMIENTO""))))) ) "),"ACTIVA") -> ACTIVA | N29: =V29 -> Patxi | O29: =W29 | S29: FALSE | T29: CLOSED / WON | U29: Girona | V29: Patxi
A30: acc_029 | B30: Stop Supermercado | C30: =IFERROR(__xludf.DUMMYFUNCTION("IFS( REGEXMATCH(LOWER(TRIM(N30)),""nico""), ""us_001"", REGEXMATCH(LOWER(TRIM(N30)),""alfonso""), ""us_002"", REGEXMATCH(LOWER(TRIM(N30)),""patxi""), ""us_003"", REGEXMATCH(LOWER(TRIM(N30)),""martin""), ""us_004"", TRUE, ""us_999"" )"),"us_001") -> us_001 | D30: =IFERROR(__xludf.DUMMYFUNCTION("""COMPUTED_VALUE"""),"us_001") -> us_001 | E30: Horeca | F30: =IFERROR(__xludf.DUMMYFUNCTION("LET( s, UPPER(TRIM(N30)), IF(REGEXMATCH(s,""CLOSED.*WON""), ""ACTIVA"", IF(REGEXMATCH(s,""CLOSED.*LOST""), ""FALLIDA"", IF(REGEXMATCH(s,""CONTACT.*NEXT.*SEASON""), ""POTENCIAL"", IF(REGEXMATCH(s,""\bLEAD\b""), ""LEAD"", IF(REGEXMATCH(s,""INTER"&"EST|POTENTIAL""), ""SEGUIMIENTO"", ""SEGUIMIENTO""))))) ) "),"SEGUIMIENTO") -> SEGUIMIENTO | G30: Placement | H30: =IFERROR(__xludf.DUMMYFUNCTION("IFS( REGEXMATCH(LOWER(TRIM(U30)),""barcelona""), ""acc_139"", REGEXMATCH(LOWER(TRIM(U30)),""madrid""), ""acc_148"", REGEXMATCH(LOWER(TRIM(U30)),""zaragoza""), ""acc_149"", REGEXMATCH(LOWER(TRIM(U30)),""ibiza""), ""acc_140"", REGEXMATCH(LOWER(TRI"&"M(U30)),""mallorca""), ""acc_140"", REGEXMATCH(LOWER(TRIM(U30)),""menorca""), ""acc_150"", TRUE, """" ) "),"acc_140") -> acc_140 | K30: Placement | L30: =IFERROR(__xludf.DUMMYFUNCTION("LET( s, UPPER(TRIM(T30)), IF(REGEXMATCH(s,""CLOSED.*WON""), ""ACTIVA"", IF(REGEXMATCH(s,""CLOSED.*LOST""), ""FALLIDA"", IF(REGEXMATCH(s,""CONTACT.*NEXT.*SEASON""), ""POTENCIAL"", IF(REGEXMATCH(s,""\bLEAD\b""), ""LEAD"", IF(REGEXMATCH(s,""INTER"&"EST|POTENTIAL""), ""SEGUIMIENTO"", ""SEGUIMIENTO""))))) ) "),"ACTIVA") -> ACTIVA | N30: =V30 -> Nico | O30: =W30 -> 1 caja | S30: FALSE | T30: CLOSED / WON | U30: Ibiza | V30: Nico | W30: 1 caja
