Workbook

Sheet Sales Santa Brisa Europe SL
A1: DATE | B1: MONTH | C1: WEEK | D1: YEAR | E1: ORDER NR | F1: CUSTOMER NAME | G1: CATEGORY | H1: LOTE | I1: SELLER (Martin, Nico, etc) | J1: 750 CASES | K1: 750 BOTTLE | L1: PRICE | M1: PAID | N1: INVOICED | O1: NEW CLIENT | P1: COUNTRY | Q1: AREA
A2: 45909 | B2: 9 | C2: 37 | D2: 2025 | E2: F25005 | F2: Real Club de Golf de Sotongrande | G2: Directa a Punto de Venta | I2: Alfonso | J2: 5 | K2: 30 | M2: 508.2 | N2: Facturado | P2: ESP
A3: 45926 | B3: 9 | C3: =WEEKNUM((A3)) -> 39 | D3: 2025 | E3: 2500018 | F3: Escola | G3: Distribuidor | I3: Patxi | J3: 50 | K3: =J3*6 -> 300 | M3: 4064.45 | N3: Facturado | P3: ESP | Q3: barcelona
A4: 45926 | B4: 9 | C4: =WEEKNUM((A4)) -> 39 | D4: 2025 | E4: 2500017 | F4: Escola | G4: Distribuidor | I4: Patxi | J4: 10 | K4: =J4*6 -> 60 | M4: 689.7 | N4: Facturado | P4: ESP | Q4: barcelona
A5: 45926 | B5: 9 | C5: =WEEKNUM((A5)) -> 39 | D5: 2025 | E5: 2500016 | F5: Islacatavinos | G5: Distribuidor | I5: Martin | J5: 10 | K5: =J5*6 -> 60 | M5: 689.7 | N5: Facturado | P5: ESP | Q5: mallorca
A6: 45926 | B6: 9 | C6: =WEEKNUM((A6)) -> 39 | D6: 2025 | E6: 2500015 | F6: Bodegas Jaime | G6: Distribuidor | I6: Martin | J6: 10 | K6: =J6*6 -> 60 | M6: 689.7 | N6: Facturado | P6: ESP | Q6: zaragoza
A7: 45926 | B7: 9 | C7: =WEEKNUM((A7)) -> 39 | D7: 2025 | E7: 2500013 | F7: Importaciones Cuesta | G7: Distribuidor | I7: Martin | J7: =K7/6 -> 24.833333 | K7: 149 | M7: 1442,32 | N7: Facturado | P7: ESP | Q7: Madrid
A8: 13/09/25 | B8: 9 | C8: 37 | D8: 2025 | E8: F25009 | F8: Importaciones Cuesta | G8: Distribuidor | I8: Martin | J8: 16.5 | K8: 99 | M8: 958.32 | N8: Facturado | P8: ESP
A9: 46000 | B9: 9 | C9: 37 | D9: 2025 | E9: F25008 | F9: Devnis Menorca | G9: Distribuidor | I9: Miguel | J9: 15 | K9: 90 | M9: 1043.62 | N9: Facturado | P9: ESP
A10: 45942 | B10: 9 | C10: 37 | D10: 2025 | E10: F25007 | F10: Devins Menorca | G10: Distribuidor | I10: Miguel | J10: 120 | K10: 720 | M10: 7972.73 | N10: Facturado | P10: ESP
A11: 45908 | B11: 9 | C11: =WEEKNUM((A11)) -> 37 | D11: 2025 | E11: F25006 | F11: Servilline Foods | G11: Distribuidor | I11: Martin | J11: =K11/6 -> 20 | K11: 120 | M11: 1380 | N11: Facturado | P11: ESP | Q11: Zaragoza
A12: 45929 | B12: 9 | C12: =WEEKNUM((A12)) -> 40 | D12: 2025 | E12: #1054 | F12: Venta Online | G12: Venta Online | I12: Nico | J12: 1 | K12: 6 | M12: 105.6 | N12: Facturado | P12: ESP | Q12: N/A
A13: 26 septiembre 25 | B13: 9 | C13: 39 | D13: 2025 | E13: #1054 | F13: Venta Online | G13: Venta Online | I13: Nico | J13: 0.33 | K13: 2 | M13: 44.9 | N13: Facturado | P13: ESP | Q13: N/A
A14: 45916 | B14: 9 | C14: =WEEKNUM((A14)) -> 38 | D14: 2025 | E14: #1053 | F14: Venta Online | G14: Venta Online | I14: Nico | J14: 1 | K14: 6 | M14: 105.6 | N14: Facturado | P14: ESP | Q14: N/A
A15: 45912 | B15: 9 | C15: =WEEKNUM((A15)) -> 37 | D15: 2025 | E15: #1052 | F15: Venta Online | G15: Venta Online | I15: Nico | J15: =K15/6 -> 0.33333333 | K15: 2 | M15: 54.5 | N15: Facturado | P15: ESP | Q15: N/A
A16: 45909 | B16: 9 | C16: =WEEKNUM((A16)) -> 37 | D16: 2025 | E16: #1051 | F16: Venta Online | G16: Venta Online | I16: Nico | J16: 4 | K16: =J16*6 -> 24 | M16: 342.2 | N16: Facturado | P16: ESP | Q16: N/A
A17: 45905 | B17: 9 | C17: =WEEKNUM((A17)) -> 36 | D17: 2025 | E17: #1050 | F17: Venta Online | G17: Venta Online | I17: Nico | J17: =K17/6 -> 0.33333333 | K17: 2 | M17: 54.5 | N17: Facturado | P17: ESP | Q17: N/A
A18: 45902 | B18: 9 | C18: =WEEKNUM((A18)) -> 36 | D18: 2025 | E18: #1049 | F18: Venta Online | G18: Venta Online | I18: Nico | J18: =K18/6 -> 1 | K18: 6 | M18: 105.6 | N18: Facturado | P18: ESP | Q18: N/A
A19: 45926 | B19: 9 | C19: =WEEKNUM((A19)) -> 39 | D19: 2025 | E19: 2500014 | F19: Quirites | G19: Venta Privada | I19: Alfonso | J19: 4 | K19: =J19*6 -> 24 | M19: 333.96 | N19: Facturado | P19: ESP | Q19: Madrid | R19: =S -> #NAME?
A20: 45926 | B20: 9 | C20: =WEEKNUM((A20)) -> 39 | D20: 2025 | E20: 2500012 | F20: Miguel garcía | G20: Venta Privada | I20: Alfonso | J20: 5 | K20: =J20*6 -> 30 | M20: 417.45 | N20: Facturado | P20: ESP | Q20: Madrid
A21: 45926 | B21: 9 | C21: =WEEKNUM((A21)) -> 39 | D21: 2025 | E21: 2500011 | F21: Alejandra de la oliva | G21: Venta Privada | I21: Alfonso | J21: 5 | K21: =J21*6 -> 30 | M21: 417.45 | N21: Facturado | P21: ESP | Q21: Madrid
A22: 45926 | B22: 9 | C22: =WEEKNUM((A22)) -> 39 | D22: 2025 | F22: Quirites Inmobiliaria | G22: Venta Privada | I22: Martin | J22: =K22/6 -> 6 | K22: 36 | M22: 414 | N22: Facturado | P22: ESP | Q22: Madrid | R22: 2 envíos en consgina
A23: 13/09/25 | B23: 9 | C23: 37 | D23: 2025 | E23: F250010 | F23: Ingo Gestión de activos | G23: Venta Privada | I23: Martin | J23: 4 | K23: 24 | M23: 232.32 | N23: Facturado | R23: AÑADIR LAS MUESTRAS
A24: 45900 | B24: 8 | C24: =WEEKNUM((A24)) -> 36 | D24: 2025 | E24: #1048 | F24: Venta Online | G24: Venta Online | I24: Nico | J24: =K24/6 -> 5 | K24: 30 | M24: 660 | N24: Facturado | P24: ESP | Q24: N/A
A25: 45900 | B25: 8 | C25: =WEEKNUM((A25)) -> 36 | D25: 2025 | E25: #1047 | F25: Venta Online | G25: Venta Online | I25: Nico | J25: =K25/6 -> 0.16666667 | K25: 1 | M25: 31.5 | N25: Facturado | P25: ESP | Q25: N/A
A26: 45900 | B26: 8 | C26: =WEEKNUM((A26)) -> 36 | D26: 2025 | E26: #1046 | F26: Venta Online | G26: Venta Online | I26: Nico | J26: =K26/6 -> 1 | K26: 6 | M26: 105.6 | N26: Facturado | P26: ESP | Q26: N/A
A27: 45897 | B27: 8 | C27: =WEEKNUM((A27)) -> 35 | D27: 2025 | E27: #1045 | F27: Venta Online | G27: Venta Online | I27: Nico | J27: =K27/6 -> 1 | K27: 6 | M27: 132 | N27: Facturado | P27: ESP | Q27: N/A
A28: 45896 | B28: 8 | C28: =WEEKNUM((A28)) -> 35 | D28: 2025 | E28: #1043 | F28: Venta Online | G28: Venta Online | I28: Nico | J28: =K28/6 -> 0.16666667 | K28: 1 | M28: 26.5 | N28: Facturado | P28: ESP | Q28: N/A
A29: 45894 | B29: 8 | C29: =WEEKNUM((A29)) -> 35 | D29: 2025 | E29: #1042 | F29: Venta Online | G29: Venta Online | I29: Nico | J29: =K29/6 -> 1 | K29: 6 | M29: 105.6 | N29: Facturado | P29: ESP | Q29: N/A
A30: 45892 | B30: 8 | C30: =WEEKNUM((A30)) -> 34 | D30: 2025 | E30: #1041 | F30: Venta Online | G30: Venta Online | I30: Nico | J30: =K30/6 -> 1 | K30: 6 | M30: 132 | N30: Facturado | P30: ESP | Q30: N/A
A31: 45891 | B31: 8 | C31: =WEEKNUM((A31)) -> 34 | D31: 2025 | E31: #1040 | F31: Venta Online | G31: Venta Online | I31: Nico | J31: =K31/6 -> 1 | K31: 6 | M31: 66 | N31: Facturado | P31: ESP | Q31: N/A
A32: 45889 | B32: 8 | C32: =WEEKNUM((A32)) -> 34 | D32: 2025 | E32: #1038 | F32: Venta Online | G32: Venta Online | I32: Nico | J32: =K32/6 -> 1 | K32: 6 | M32: 105.6 | N32: Facturado | P32: ESP | Q32: N/A
A33: 45888 | B33: 8 | C33: =WEEKNUM((A33)) -> 34 | D33: 2025 | E33: #1036 | F33: Venta Online | G33: Venta Online | I33: Nico | J33: =K33/6 -> 1 | K33: 6 | M33: 132 | N33: Facturado | P33: ESP | Q33: N/A
A34: 45886 | B34: 8 | C34: =WEEKNUM((A34)) -> 34 | D34: 2025 | E34: #1035 | F34: Venta Online | G34: Venta Online | I34: Nico | J34: =K34/6 -> 1 | K34: 6 | M34: 105.6 | N34: Facturado | P34: ESP | Q34: N/A
A35: 45879 | B35: 8 | C35: =WEEKNUM((A35)) -> 33 | D35: 2025 | E35: #1032 | F35: Venta Online | G35: Venta Online | I35: Nico | J35: =K35/6 -> 1 | K35: 6 | M35: 105.6 | N35: Facturado | P35: ESP | Q35: N/A
A36: 45879 | B36: 8 | C36: =WEEKNUM((A36)) -> 33 | D36: 2025 | F36: Venta Online | G36: Venta Online | I36: Nico | J36: =K36/6 -> 0.33333333 | K36: 2 | M36: 47.78 | N36: Facturado a RTDM Corp (por error) | P36: ESP | Q36: N/A
A37: 45878 | B37: 8 | C37: =WEEKNUM((A37)) -> 32 | D37: 2025 | E37: #1031 | F37: Venta Online | G37: Venta Online | I37: Nico | J37: =K37/6 -> 0.33333333 | K37: 2 | M37: 44.9 | N37: Facturado | P37: ESP | Q37: N/A
A38: 45875 | B38: 8 | C38: =WEEKNUM((A38)) -> 32 | D38: 2025 | E38: #1029 | F38: Venta Online | G38: Venta Online | I38: Nico | J38: =K38/6 -> 1 | K38: 6 | M38: 105.6 | N38: Facturado | P38: ESP | Q38: N/A
A39: 45875 | B39: 8 | C39: =WEEKNUM((A39)) -> 32 | D39: 2025 | E39: #1028 | F39: Venta Online | G39: Venta Online | I39: Nico | J39: =K39/6 -> 1 | K39: 6 | M39: 105.6 | N39: Facturado | P39: ESP | Q39: N/A
A40: 45874 | B40: 8 | C40: =WEEKNUM((A40)) -> 32 | D40: 2025 | E40: #1027 | F40: Venta Online | G40: Venta Online | I40: Nico | J40: =K40/6 -> 0.33333333 | K40: 2 | M40: 44.9 | N40: Facturado | P40: ESP | Q40: N/A
...

Sheet Pivot Table 1

Sheet Consigna POR FACTURAR
A1: DATE | B1: MONTH | C1: WEEK | D1: YEAR | E1: ORDER NR | F1: CUSTOMER NAME | G1: LOTE | H1: SELLER (Martin, Nico, etc) | I1: 750 CASES | J1: 750 BOTTLE | K1: PRICE | L1: PAID | N1: INVOICED | O1: NEW CLIENT | P1: CHANNEL | Q1: CATEGORY | R1: COUNTRY | S1: AREA
A3: 29-9-25 | D3: 2025 | F3: De Vins | H3: Martin | N3: Facturado
A4: 45778 | D4: 2025 | F4: Importaciones Cuesta | H4: Martin | I4: 30 | L4: 1742 | N4: Consigna | Q4: Importaciones Cuesta | R4: ESP | S4: Madrid
A5: 45813 | D5: 2025 | F5: Isla Catavinos | H5: Martin | I5: 40 | J5: =I5*6 -> 240 | L5: =J5*11.5*1.21 -> 3339.6 | N5: Consigna | Q5: Isla Catavinos | R5: ESP | S5: Mallorca/ Ibiza
A6: 45813 | B6: 6 | C6: =WEEKNUM((A6)) -> 23 | D6: 2025 | F6: Distribuiciones Alvarez | H6: Martin | I6: 30 | J6: =I6*6 -> 180 | L6: =J6*11.2*1.21 -> 2439.36 | N6: Consigna | Q6: Isla Catavinos | R6: ESP | S6: Mallorca/ Ibiza

Sheet Copy of ES Sales Plan (by Distr
D1: ACTUALIZAR
E2: 2025
D3: May | F3: June | H3: July | J3: August | L3: September | N3: October | P3: November | R3: December | T3: YTD 2025 | U3: Total
C4: Metric | D4: Actual | E4: Plan | F4: Actual | G4: Plan | H4: Actual | I4: Plan | J4: Actual | K4: Plan | L4: Actual | M4: Plan | N4: Actual | O4: Plan | P4: Actual | Q4: Plan | R4: Actual | S4: Plan | U4: Plan 2025
A5: Sales in USD | B5: Direct Sales | C5: EUR | E5: 0 | G5: 0 | I5: 13760 | K5: 13760 | M5: 22000 | O5: 26400 | Q5: 31680 | S5: 38016 | T5: =R5+P5+N5+L5+J5+H5+F5+D5 -> 0 | U5: =S5+Q5+O5+M5+K5+I5+G5+E5 -> 145616
B6: Mallorca/ Ibiza | C6: EUR | E6: 0 | G6: 0 | I6: 0 | K6: 0 | M6: 0 | O6: 0 | Q6: 0 | S6: 0 | T6: =R6+P6+N6+L6+J6+H6+F6+D6 -> 0 | U6: =S6+Q6+O6+M6+K6+I6+G6+E6 -> 0
B7: Cuesta | C7: EUR | E7: 0 | G7: 0 | I7: 0 | K7: 0 | M7: 0 | O7: 0 | Q7: 0 | S7: 0 | T7: =R7+P7+N7+L7+J7+H7+F7+D7 -> 0 | U7: =S7+Q7+O7+M7+K7+I7+G7+E7 -> 0
B8: Total | C8: EUR | D8: 1775.87 | E8: =sum(E5:E7) -> 0 | F8: 1825.25 | G8: =sum(G5:G7) -> 0 | H8: 5715.67 | I8: =sum(I5:I7) -> 13760 | J8: 2735.1 | K8: =sum(K5:K7) -> 13760 | L8: 20625 | M8: =sum(M5:M7) -> 22000 | O8: =sum(O5:O7) -> 26400 | Q8: =sum(Q5:Q7) -> 31680 | S8: =sum(S5:S7) -> 38016 | T8: =R8+P8+N8+L8+J8+H8+F8+D8 -> 32676.89 | U8: =S8+Q8+O8+M8+K8+I8+G8+E8 -> 145616
A10: Sales in # Cases | C10: #
B11: Álvarez | C11: Cajas 6x (750ml) | E11: 0 | G11: 0 | I11: 0 | K11: 0 | M11: 0 | O11: 120 | Q11: 240 | S11: 240 | T11: =R11+P11+N11+L11+J11+H11+F11+D11 -> 0 | U11: =S11+Q11+O11+M11+K11+I11+G11+E11 -> 600
C12: Botellas (750ml) | O12: =O11*6 -> 720 | Q12: =Q11*6 -> 1440
B13: Escolá | C13: Cajas 6x (750ml) | E13: 0 | G13: 0 | I13: 0 | K13: 0 | M13: 0 | O13: 120 | Q13: 240 | S13: 240 | T13: =R13+P13+N13+L13+J13+H13+F13+D13 -> 0 | U13: =S13+Q13+O13+M13+K13+I13+G13+E13 -> 600
C14: Botellas (750ml) | O14: =O13*6 -> 720 | Q14: =Q13*6 -> 1440
B15: Goya | C15: Cajas 6x (750ml) | E15: 0 | G15: 0 | I15: 0 | K15: 0 | M15: 0 | O15: 20 | Q15: 30 | S15: 30 | T15: =R15+P15+N15+L15+J15+H15+F15+D15 -> 0 | U15: =S15+Q15+O15+M15+K15+I15+G15+E15 -> 80
C16: Botellas (750ml) | O16: =O15*6 -> 120 | Q16: =Q15*6 -> 180
B17: Isla Catavinos | C17: Cajas 6x (750ml) | E17: 0 | G17: 0 | I17: 0 | K17: 0 | M17: 0 | O17: 40 | Q17: 40 | S17: 40 | T17: =R17+P17+N17+L17+J17+H17+F17+D17 -> 0 | U17: =S17+Q17+O17+M17+K17+I17+G17+E17 -> 120
C18: Botellas (750ml) | O18: =O17*6 -> 240 | Q18: =Q17*6 -> 240
B19: De Vins | C19: Cajas 6x (750ml) | E19: 0 | G19: 0 | I19: 0 | K19: 0 | M19: 0 | O19: 10 | Q19: 10 | S19: 10 | T19: =R19+P19+N19+L19+J19+H19+F19+D19 -> 0 | U19: =S19+Q19+O19+M19+K19+I19+G19+E19 -> 30
C20: Botellas (750ml) | O20: =O19*6 -> 60 | Q20: =Q19*6 -> 60
B21: Distrubuidor Gerona | C21: Cajas 6x (750ml) | E21: 0 | G21: 0 | I21: 0 | K21: 0 | M21: 0 | O21: 20 | Q21: 20 | S21: 20 | T21: =R21+P21+N21+L21+J21+H21+F21+D21 -> 0 | U21: =S21+Q21+O21+M21+K21+I21+G21+E21 -> 60
C22: Botellas (750ml) | O22: =O21*6 -> 120 | Q22: =Q21*6 -> 120
B23: Direct Sales | C23: Cajas 6x (750ml) | E23: 0 | G23: 0 | I23: 0 | K23: 0 | M23: 0 | O23: 10 | Q23: 0 | S23: 0 | T23: =R23+P23+N23+L23+J23+H23+F23+D23 -> 0 | U23: =S23+Q23+O23+M23+K23+I23+G23+E23 -> 10
C24: Botellas (750ml) | O24: =O23*6 -> 60 | Q24: =Q23*6 -> 0
B25: Total | C25: # Cajas | D25: =D11+D13+D15+D17+D19+D21+D23 -> 0 | E25: =E11+E13+E15+E17+E19+E21+E23 -> 0 | F25: =F11+F13+F15+F17+F19+F21+F23 -> 0 | G25: =G11+G13+G15+G17+G19+G21+G23 -> 0 | H25: =H11+H13+H15+H17+H19+H21+H23 -> 0 | I25: =I11+I13+I15+I17+I19+I21+I23 -> 0 | J25: =J11+J13+J15+J17+J19+J21+J23 -> 0 | K25: =K11+K13+K15+K17+K19+K21+K23 -> 0 | ... S25: =S11+S13+S15+S17+S19+S21+S23 -> 580 | T25: =sum(T17:T18) -> 0 | U25: =S25+Q25+O25+M25+K25+I25+G25+E25 -> 1500
B26: Total | C26: # Botellas | D26: =D12+D14+D16+D18+D20+D22+D24 -> 0 | E26: =E12+E14+E16+E18+E20+E22+E24 -> 0 | F26: =F12+F14+F16+F18+F20+F22+F24 -> 0 | G26: =G12+G14+G16+G18+G20+G22+G24 -> 0 | H26: =H12+H14+H16+H18+H20+H22+H24 -> 0 | I26: =I12+I14+I16+I18+I20+I22+I24 -> 0 | J26: =J12+J14+J16+J18+J20+J22+J24 -> 0 | K26: =K12+K14+K16+K18+K20+K22+K24 -> 0 | ... S26: =S12+S14+S16+S18+S20+S22+S24 -> 0 | T26: =sum(T18:T19) -> 0 | U26: =S26+Q26+O26+M26+K26+I26+G26+E26 -> 5520

Sheet Cierres Mensual
C1: 5 | D1: 6 | E1: 7 | F1: 8 | G1: 9 | H1: 10 | I1: 11 | J1: 12
C2: Mayo | D2: Junio | E2: Julio | F2: Agosto | G2: Septiembre | H2: Octubre | I2: Noviembre | J2: Diciembre | L2: YTD
B3: Ventas en EUR | C3: =sumif('Sales Santa Brisa Europe SL'!$B:$B,"5",'Sales Santa Brisa Europe SL'!$M:$M) -> 47.99 | D3: =sumif('Sales Santa Brisa Europe SL'!$B:$B,"6",'Sales Santa Brisa Europe SL'!$M:$M) -> 943.25 | E3: =sumif('Sales Santa Brisa Europe SL'!$B:$B,"7",'Sales Santa Brisa Europe SL'!$M:$M) -> 3999.67 | F3: =sumif('Sales Santa Brisa Europe SL'!$B:$B,"8",'Sales Santa Brisa Europe SL'!$M:$M) -> 2782.88 | G3: =sumif('Sales Santa Brisa Europe SL'!$B:$B,"9",'Sales Santa Brisa Europe SL'!$M:$M) -> 20624.5 | H3: =sumif('Sales Santa Brisa Europe SL'!$B:$B,"10",'Sales Santa Brisa Europe SL'!$M:$M) -> 0 | I3: =sumif('Sales Santa Brisa Europe SL'!$B:$B,"11",'Sales Santa Brisa Europe SL'!$M:$M) -> 0 | J3: =sumif('Sales Santa Brisa Europe SL'!$B:$B,"12",'Sales Santa Brisa Europe SL'!$M:$M) -> 0 | L3: =sum(B3:J3) -> 28398.29
B4: Ventas en Botellas | C4: =sumif('Sales Santa Brisa Europe SL'!$B:$B,C1,'Sales Santa Brisa Europe SL'!$K:$K) -> 1 | D4: =sumif('Sales Santa Brisa Europe SL'!$B:$B,D1,'Sales Santa Brisa Europe SL'!$K:$K) -> 106 | E4: =sumif('Sales Santa Brisa Europe SL'!$B:$B,E1,'Sales Santa Brisa Europe SL'!$K:$K) -> 326 | F4: =sumif('Sales Santa Brisa Europe SL'!$B:$B,F1,'Sales Santa Brisa Europe SL'!$K:$K) -> 147 | G4: =sumif('Sales Santa Brisa Europe SL'!$B:$B,G1,'Sales Santa Brisa Europe SL'!$K:$K) -> 1880 | H4: =sumif('Sales Santa Brisa Europe SL'!$B:$B,H1,'Sales Santa Brisa Europe SL'!$K:$K) -> 0 | I4: =sumif('Sales Santa Brisa Europe SL'!$B:$B,I1,'Sales Santa Brisa Europe SL'!$K:$K) -> 0 | J4: =sumif('Sales Santa Brisa Europe SL'!$B:$B,J1,'Sales Santa Brisa Europe SL'!$K:$K) -> 0 | L4: =sum(B4:J4) -> 2460
B6: Ventas en Cajas | C6: =C4/6 -> 0.16666667 | D6: =D4/6 -> 17.666667 | E6: =E4/6 -> 54.333333 | F6: =F4/6 -> 24.5 | G6: =G4/6 -> 313.33333 | H6: =H4/6 -> 0 | I6: =I4/6 -> 0 | J6: =J4/6 -> 0 | L6: =sum(D6:J6) -> 409.83333
C8: Mayo | D8: Junio | E8: Julio | F8: Agosto | G8: Septiembre | H8: Octubre | I8: Noviembre | J8: Diciembre
B9: Distribuidor | C9: =SUMIFS('Sales Santa Brisa Europe SL'!$M:$M,'Sales Santa Brisa Europe SL'!$B:$B, C$1,'Sales Santa Brisa Europe SL'!$G:$G, $B$9) -> 0 | D9: =SUMIFS('Sales Santa Brisa Europe SL'!$M:$M,'Sales Santa Brisa Europe SL'!$B:$B, D$1,'Sales Santa Brisa Europe SL'!$G:$G, $B$9) -> 0 | E9: =SUMIFS('Sales Santa Brisa Europe SL'!$M:$M,'Sales Santa Brisa Europe SL'!$B:$B, E$1,'Sales Santa Brisa Europe SL'!$G:$G, $B$9) -> 0 | F9: =SUMIFS('Sales Santa Brisa Europe SL'!$M:$M,'Sales Santa Brisa Europe SL'!$B:$B, F$1,'Sales Santa Brisa Europe SL'!$G:$G, $B$9) -> 0 | G9: =SUMIFS('Sales Santa Brisa Europe SL'!$M:$M,'Sales Santa Brisa Europe SL'!$B:$B, G$1,'Sales Santa Brisa Europe SL'!$G:$G, $B$9) -> 17488.22 | H9: =SUMIFS('Sales Santa Brisa Europe SL'!$M:$M,'Sales Santa Brisa Europe SL'!$B:$B, H$1,'Sales Santa Brisa Europe SL'!$G:$G, $B$9) -> 0 | I9: =SUMIFS('Sales Santa Brisa Europe SL'!$M:$M,'Sales Santa Brisa Europe SL'!$B:$B, I$1,'Sales Santa Brisa Europe SL'!$G:$G, $B$9) -> 0 | J9: =SUMIFS('Sales Santa Brisa Europe SL'!$M:$M,'Sales Santa Brisa Europe SL'!$B:$B, J$1,'Sales Santa Brisa Europe SL'!$G:$G, $B$9) -> 0 | L9: =sum(B9:J9) -> 17488.22
B10: Venta Online | C10: =SUMIFS('Sales Santa Brisa Europe SL'!$M:$M,'Sales Santa Brisa Europe SL'!$B:$B, C$1,'Sales Santa Brisa Europe SL'!$G:$G, $B$10) -> 47.99 | D10: =SUMIFS('Sales Santa Brisa Europe SL'!$M:$M,'Sales Santa Brisa Europe SL'!$B:$B, D$1,'Sales Santa Brisa Europe SL'!$G:$G, $B$10) -> 175.25 | E10: =SUMIFS('Sales Santa Brisa Europe SL'!$M:$M,'Sales Santa Brisa Europe SL'!$B:$B, E$1,'Sales Santa Brisa Europe SL'!$G:$G, $B$10) -> 2145.67 | F10: =SUMIFS('Sales Santa Brisa Europe SL'!$M:$M,'Sales Santa Brisa Europe SL'!$B:$B, F$1,'Sales Santa Brisa Europe SL'!$G:$G, $B$10) -> 2782.88 | G10: =SUMIFS('Sales Santa Brisa Europe SL'!$M:$M,'Sales Santa Brisa Europe SL'!$B:$B, G$1,'Sales Santa Brisa Europe SL'!$G:$G, $B$10) -> 812.9 | H10: =SUMIFS('Sales Santa Brisa Europe SL'!$M:$M,'Sales Santa Brisa Europe SL'!$B:$B, H$1,'Sales Santa Brisa Europe SL'!$G:$G, $B$10) -> 0 | I10: =SUMIFS('Sales Santa Brisa Europe SL'!$M:$M,'Sales Santa Brisa Europe SL'!$B:$B, I$1,'Sales Santa Brisa Europe SL'!$G:$G, $B$10) -> 0 | J10: =SUMIFS('Sales Santa Brisa Europe SL'!$M:$M,'Sales Santa Brisa Europe SL'!$B:$B, J$1,'Sales Santa Brisa Europe SL'!$G:$G, $B$10) -> 0 | L10: =sum(B10:J10) -> 5964.69
B11: Venta Privada | C11: =SUMIFS('Sales Santa Brisa Europe SL'!$M:$M,'Sales Santa Brisa Europe SL'!$B:$B, C$1,'Sales Santa Brisa Europe SL'!$G:$G, $B$11) -> 0 | D11: =SUMIFS('Sales Santa Brisa Europe SL'!$M:$M,'Sales Santa Brisa Europe SL'!$B:$B, D$1,'Sales Santa Brisa Europe SL'!$G:$G, $B$11) -> 768 | E11: =SUMIFS('Sales Santa Brisa Europe SL'!$M:$M,'Sales Santa Brisa Europe SL'!$B:$B, E$1,'Sales Santa Brisa Europe SL'!$G:$G, $B$11) -> 1854 | F11: =SUMIFS('Sales Santa Brisa Europe SL'!$M:$M,'Sales Santa Brisa Europe SL'!$B:$B, F$1,'Sales Santa Brisa Europe SL'!$G:$G, $B$11) -> 0 | G11: =SUMIFS('Sales Santa Brisa Europe SL'!$M:$M,'Sales Santa Brisa Europe SL'!$B:$B, G$1,'Sales Santa Brisa Europe SL'!$G:$G, $B$11) -> 1815.18 | H11: =SUMIFS('Sales Santa Brisa Europe SL'!$M:$M,'Sales Santa Brisa Europe SL'!$B:$B, H$1,'Sales Santa Brisa Europe SL'!$G:$G, $B$11) -> 0 | I11: =SUMIFS('Sales Santa Brisa Europe SL'!$M:$M,'Sales Santa Brisa Europe SL'!$B:$B, I$1,'Sales Santa Brisa Europe SL'!$G:$G, $B$11) -> 0 | J11: =SUMIFS('Sales Santa Brisa Europe SL'!$M:$M,'Sales Santa Brisa Europe SL'!$B:$B, J$1,'Sales Santa Brisa Europe SL'!$G:$G, $B$11) -> 0 | L11: =sum(B11:J11) -> 4437.18
B12: Directa a Punto de Venta | C12: =SUMIFS('Sales Santa Brisa Europe SL'!$M:$M,'Sales Santa Brisa Europe SL'!$B:$B, C$1,'Sales Santa Brisa Europe SL'!$G:$G, $B$12) -> 0 | D12: =SUMIFS('Sales Santa Brisa Europe SL'!$M:$M,'Sales Santa Brisa Europe SL'!$B:$B, D$1,'Sales Santa Brisa Europe SL'!$G:$G, $B$12) -> 0 | E12: =SUMIFS('Sales Santa Brisa Europe SL'!$M:$M,'Sales Santa Brisa Europe SL'!$B:$B, E$1,'Sales Santa Brisa Europe SL'!$G:$G, $B$12) -> 0 | F12: =SUMIFS('Sales Santa Brisa Europe SL'!$M:$M,'Sales Santa Brisa Europe SL'!$B:$B, F$1,'Sales Santa Brisa Europe SL'!$G:$G, $B$12) -> 0 | G12: =SUMIFS('Sales Santa Brisa Europe SL'!$M:$M,'Sales Santa Brisa Europe SL'!$B:$B, G$1,'Sales Santa Brisa Europe SL'!$G:$G, $B$12) -> 508.2 | H12: =SUMIFS('Sales Santa Brisa Europe SL'!$M:$M,'Sales Santa Brisa Europe SL'!$B:$B, H$1,'Sales Santa Brisa Europe SL'!$G:$G, $B$12) -> 0 | I12: =SUMIFS('Sales Santa Brisa Europe SL'!$M:$M,'Sales Santa Brisa Europe SL'!$B:$B, I$1,'Sales Santa Brisa Europe SL'!$G:$G, $B$12) -> 0 | J12: =SUMIFS('Sales Santa Brisa Europe SL'!$M:$M,'Sales Santa Brisa Europe SL'!$B:$B, J$1,'Sales Santa Brisa Europe SL'!$G:$G, $B$12) -> 0 | L12: =sum(B12:J12) -> 508.2

Sheet Cierres Semanales
C2: Ventas EUR | D2: Ventas # Botellas
B3: 18 | C3: =sumif('Sales Santa Brisa Europe SL'!$C:$C,B3,'Sales Santa Brisa Europe SL'!$M:$M) -> 0 | D3: =sumif('Sales Santa Brisa Europe SL'!$C:$C,$B3,'Sales Santa Brisa Europe SL'!$K:$K) -> 0
B4: 19 | C4: =sumif('Sales Santa Brisa Europe SL'!$C:$C,B4,'Sales Santa Brisa Europe SL'!$M:$M) -> 0 | D4: =sumif('Sales Santa Brisa Europe SL'!$C:$C,$B4,'Sales Santa Brisa Europe SL'!$K:$K) -> 0
B5: 20 | C5: =sumif('Sales Santa Brisa Europe SL'!$C:$C,B5,'Sales Santa Brisa Europe SL'!$M:$M) -> 0 | D5: =sumif('Sales Santa Brisa Europe SL'!$C:$C,$B5,'Sales Santa Brisa Europe SL'!$K:$K) -> 0
B6: 21 | C6: =sumif('Sales Santa Brisa Europe SL'!$C:$C,B6,'Sales Santa Brisa Europe SL'!$M:$M) -> 0 | D6: =sumif('Sales Santa Brisa Europe SL'!$C:$C,$B6,'Sales Santa Brisa Europe SL'!$K:$K) -> 0
B7: 22 | C7: =sumif('Sales Santa Brisa Europe SL'!$C:$C,B7,'Sales Santa Brisa Europe SL'!$M:$M) -> 47.99 | D7: =sumif('Sales Santa Brisa Europe SL'!$C:$C,$B7,'Sales Santa Brisa Europe SL'!$K:$K) -> 1
B8: 23 | C8: =sumif('Sales Santa Brisa Europe SL'!$C:$C,B8,'Sales Santa Brisa Europe SL'!$M:$M) -> 0 | D8: =sumif('Sales Santa Brisa Europe SL'!$C:$C,$B8,'Sales Santa Brisa Europe SL'!$K:$K) -> 0
B9: 24 | C9: =sumif('Sales Santa Brisa Europe SL'!$C:$C,B9,'Sales Santa Brisa Europe SL'!$M:$M) -> 0 | D9: =sumif('Sales Santa Brisa Europe SL'!$C:$C,$B9,'Sales Santa Brisa Europe SL'!$K:$K) -> 0
B10: 25 | C10: =sumif('Sales Santa Brisa Europe SL'!$C:$C,B10,'Sales Santa Brisa Europe SL'!$M:$M) -> 0 | D10: =sumif('Sales Santa Brisa Europe SL'!$C:$C,$B10,'Sales Santa Brisa Europe SL'!$K:$K) -> 0
B11: 26 | C11: =sumif('Sales Santa Brisa Europe SL'!$C:$C,B11,'Sales Santa Brisa Europe SL'!$M:$M) -> 943.25 | D11: =sumif('Sales Santa Brisa Europe SL'!$C:$C,$B11,'Sales Santa Brisa Europe SL'!$K:$K) -> 106
B12: 27 | C12: =sumif('Sales Santa Brisa Europe SL'!$C:$C,B12,'Sales Santa Brisa Europe SL'!$M:$M) -> 1564.37 | D12: =sumif('Sales Santa Brisa Europe SL'!$C:$C,$B12,'Sales Santa Brisa Europe SL'!$K:$K) -> 186
B13: 28 | C13: =sumif('Sales Santa Brisa Europe SL'!$C:$C,B13,'Sales Santa Brisa Europe SL'!$M:$M) -> 0 | D13: =sumif('Sales Santa Brisa Europe SL'!$C:$C,$B13,'Sales Santa Brisa Europe SL'!$K:$K) -> 0
B14: 29 | C14: =sumif('Sales Santa Brisa Europe SL'!$C:$C,B14,'Sales Santa Brisa Europe SL'!$M:$M) -> 304.1 | D14: =sumif('Sales Santa Brisa Europe SL'!$C:$C,$B14,'Sales Santa Brisa Europe SL'!$K:$K) -> 14
... B34: 49 | C34: =sumif('Sales Santa Brisa Europe SL'!$C:$C,B34,'Sales Santa Brisa Europe SL'!$M:$M) -> 0 | D34: =sumif('Sales Santa Brisa Europe SL'!$C:$C,$B34,'Sales Santa Brisa Europe SL'!$K:$K) -> 0

Sheet Cuesta
A1: DATE | B1: MONTH | C1: WEEK | D1: YEAR | E1: ORDER NR | F1: CUSTOMER NAME | G1: SELLER (Martin, Nico, etc) | H1: 750 CASES | I1: 100 CASES | J1: 750 BOTTLE | K1: PRICE | L1: PAID | M1: INVOICED | N1: NEW CLIENT | O1: CHANNEL | P1: CATEGORY | Q1: COUNTRY | R1: AREA
A2: 45846 | B2: 7 | C2: =WEEKNUM((A2)) -> 28 | D2: 2025 | F2: Supermercado Melo | H2: 1 | L2: 101.64 | Q2: ESP | R2: Madrid
A3: 45845 | B3: 7 | C3: =WEEKNUM((A3)) -> 28 | D3: 2025 | F3: Cerveceria Santa Barbara | H3: 1 | L3: 84.7 | Q3: ESP | R3: Madrid
A4: 45845 | B4: 7 | C4: =WEEKNUM((A4)) -> 28 | D4: 2025 | F4: Catering The Cook | H4: 3 | L4: 304.92 | Q4: ESP | R4: Madrid
A5: 45839 | B5: 7 | C5: =WEEKNUM((A5)) -> 27 | D5: 2025 | F5: Bulo | H5: 1 | L5: 101.64 | Q5: ESP | R5: Madrid
A6: 45839 | B6: 7 | C6: =WEEKNUM((A6)) -> 27 | D6: 2025 | F6: Joselito Las Rozas | H6: 3 | L6: 304.92 | Q6: ESP | R6: Madrid
A7: 45839 | B7: 7 | C7: =WEEKNUM((A7)) -> 27 | D7: 2025 | F7: Adrede Restaurante | H7: 1 | L7: 84.7 | Q7: ESP | R7: Madrid
A8: 45830 | B8: 6 | C8: =WEEKNUM((A8)) -> 26 | D8: 2025 | F8: Grupo 2.0 | H8: 4 | L8: 406.56 | Q8: ESP | R8: Madrid
A9: 45830 | B9: 6 | C9: =WEEKNUM((A9)) -> 26 | D9: 2025 | F9: Gabys Bagels | H9: 3 | L9: 304.92 | Q9: ESP | R9: Madrid
A10: 45823 | B10: 6 | C10: =WEEKNUM((A10)) -> 25 | D10: 2025 | F10: Catering The Cook | H10: 1 | L10: 101.64 | Q10: ESP | R10: Madrid
A11: 45819 | B11: 6 | C11: =WEEKNUM((A11)) -> 24 | D11: 2025 | F11: Delirium Catering | H11: 2 | L11: 203.28 | Q11: ESP | R11: Madrid
A12: 45826 | B12: 6 | C12: =WEEKNUM((A12)) -> 25 | D12: 2025 | F12: Cerveceria Santa Barbara | H12: 2 | L12: 203.28 | Q12: ESP | R12: Madrid
A13: 45826 | B13: 6 | C13: =WEEKNUM((A13)) -> 25 | D13: 2025 | F13: Catering The Cook | H13: 3 | L13: 304.92 | Q13: ESP | R13: Madrid
... A16: 45804 | B16: 5 | C16: =WEEKNUM((A16)) -> 22 | D16: 2025 | F16: Gabys Bagels | H16: 1 | L16: 101.64 | Q16: ESP | R16: Madrid
A22: 45937 | B22: 4300990001 | C22: DISTRIBUCIONS ARAL, S.L. | D22: 1.428,00 | E22: 21,00 | F22: 299,88 | G22: 1.727,88 | H22: 1727.88 | I22: 120 | J22: 1
A23: A 196050 | B23: 45937 | C23: 4300990002 | D23: MACAVELA 136. S.L. | E23: 252,00 | F23: 21,00 | G23: 52,92 | H23: 304.92 | J23: 18 | K23: 1
A24: A 196116 | B24: 45937 | C24: 4300990006 | D24: UCALSA, S.A UNION CASTELLANA DE ALIMENTACIÓN | E24: 336,00 | F24: 21,00 | G24: 70,56 | H24: 406.56 | J24: 24 | K24: 1
A25: A 196119 | B25: 45937 | C25: 4300990007 | D25: CATERING THE COOK, S.L.U | E25: 252,00 | F25: 21,00 | G25: 52,92 | H25: 304.92 | J25: 18 | K25: 1
A26: A 197056 | B26: 45937 | C26: 4300990008 | D26: SANTA BARBARA DE CERVECERIA 2006, S.L. | E26: 120,00 | F26: 21,00 | G26: 25,20 | H26: 145.2 | J26: 12 | K26: 1
A27: A 196121 | B27: 45937 | C27: 4300990009 | D27: DELIRIUM BY LUCIA, S.L. | E27: 168,00 | F27: 21,00 | G27: 35,28 | H27: 203.28 | J27: 12 | K27: 1
A28: A 196122 | B28: 45937 | C28: 4300990007 | D28: CATERING THE COOK, S.L.U | E28: 84,00 | F28: 21,00 | G28: 17,64 | H28: 101.64 | J28: 6 | K28: 1
A29: A 196123 | B29: 45937 | C29: 4300990003 | D29: BLISS BAGELS, S.L. | E29: 252,00 | F29: 21,00 | G29: 52,92 | H29: 304.92 | I29: PAGADA | J29: 18 | K29: 1
A30: A 196124 | B30: 45937 | C30: 4300990004 | D30: LAS TABLAS PUNTO CERO | E30: 336,00 | F30: 21,00 | G30: 70,56 | H30: 406.56 | I30: PAGADA | J30: 24 | K30: 1
A31: A 196128 | B31: 45968 | C31: 4300990007 | D31: CATERING THE COOK, S.L.U | E31: 252,00 | F31: 21,00 | G31: 52,92 | H31: 304.92 | J31: 18 | K31: 1
A32: A 197055 | B32: 45968 | C32: 4300990008 | D32: SANTA BARBARA DE CERVECERIA 2006, S.L. | E32: 50,00 | F32: 21,00 | G32: 10,50 | H32: 60.5 | J32: 5 | K32: 1
A33: A 196130 | B33: 45968 | C33: 4300990012 | D33: SUPERMERCADO MELO, S.L. | E33: 84,00 | F33: 21,00 | G33: 17,64 | H33: 101.64 | J33: 6 | K33: 1
A34: A 198589 | B34: 45666 | C34: 4300990013 | D34: VOLVER AL ORIGEN - TABERNA PEDRAZA | E34: 84,00 | F34: 21,00 | G34: 17,64 | H34: 101.64 | J34: 6
A35: Cuesta sin facturar | H35: =SUM(H22:H34) -> 4474.58
A36: Cuesta facturado | H36: 862.5
H37: 232.32
H38: 1043.62
H40: 1219.68
H41: 508.2
H42: =SUM(H35:H41) -> 8340.9
H43: =SUM(H35:H42) -> 16681.8

Sheet ES Sales Plan (by Distributor)
E1: 2025
D2: May | F2: June | H2: July | J2: YTD 2025 | K2: August | M2: September | O2: October | Q2: November | S2: December | U2: Total
C3: Metric | D3: Actual | E3: Plan | F3: Actual | G3: Plan | H3: Actual | I3: Plan | K3: Actual | L3: Plan | M3: Actual | N3: Plan | O3: Actual | P3: Plan | Q3: Actual | R3: Plan | S3: Actual | T3: Plan | U3: Plan 2025
A4: Sales in USD | B4: Direct Sales | C4: EUR | E4: 0 | G4: 0 | I4: 13760 | J4: =S4+Q4+O4+M4+K4+H4+F4+D4 -> 0 | L4: 13760 | N4: 22000 | P4: 26400 | R4: 31680 | T4: 38016 | U4: =T4+R4+P4+N4+L4+I4+G4+E4 -> 145616
B5: Mallorca/ Ibiza | C5: EUR | E5: 0 | G5: 0 | I5: 0 | J5: =S5+Q5+O5+M5+K5+H5+F5+D5 -> 0 | L5: 0 | N5: 0 | P5: 0 | R5: 0 | T5: 0 | U5: =T5+R5+P5+N5+L5+I5+G5+E5 -> 0
B6: Cuesta | C6: EUR | E6: 0 | G6: 0 | I6: 0 | J6: =S6+Q6+O6+M6+K6+H6+F6+D6 -> 0 | L6: 0 | N6: 0 | P6: 0 | R6: 0 | T6: 0 | U6: =T6+R6+P6+N6+L6+I6+G6+E6 -> 0
B7: Total | C7: EUR | D7: 1775.87 | E7: =sum(E4:E6) -> 0 | F7: 1825.25 | G7: =sum(G4:G6) -> 0 | H7: 5715.67 | I7: =sum(I4:I6) -> 13760 | J7: =S7+Q7+O7+M7+K7+H7+F7+D7 -> 32676.89 | K7: 2735.1 | L7: =sum(L4:L6) -> 13760 | M7: 20625 | N7: =sum(N4:N6) -> 22000 | P7: =sum(P4:P6) -> 26400 | R7: =sum(R4:R6) -> 31680 | T7: =sum(T4:T6) -> 38016 | U7: =T7+R7+P7+N7+L7+I7+G7+E7 -> 145616
A9: Sales in # Cases | C9: # Cases (6x)
B10: Direct Sales | C10: 750ml | E10: 0 | G10: 0 | I10: 0 | J10: =S10+Q10+O10+M10+K10+H10+F10+D10 -> 0 | L10: 0 | N10: 0 | P10: 0 | R10: 0 | T10: 0 | U10: =T10+R10+P10+N10+L10+I10+G10+E10 -> 0
C11: 100ml
B12: Mallorca/ Ibiza | C12: 750ml | E12: 0 | G12: 0 | I12: 0 | J12: =S12+Q12+O12+M12+K12+H12+F12+D12 -> 0 | L12: 0 | N12: 0 | P12: 0 | R12: 0 | T12: 0 | U12: =T12+R12+P12+N12+L12+I12+G12+E12 -> 0
C13: 100ml
B14: Cuesta | C14: 750ml | E14: 0 | G14: 0 | I14: 287 | J14: =S14+Q14+O14+M14+K14+H14+F14+D14 -> 0 | L14: 287 | N14: 458 | P14: 504 | R14: 555 | T14: 610 | U14: =T14+R14+P14+N14+L14+I14+G14+E14 -> 2701
C15: 100ml
B16: Total | C16: # Cases | D16: 20.17 | F16: 42.67 | H16: 78 | I16: =sum(I10:I14) -> 287 | J16: =sum(J10:J14) -> 0 | K16: 24 | L16: =sum(L10:L14) -> 287 | M16: 313.33 | N16: =sum(N10:N14) -> 458 | O16: =sum(O10:O14) -> 0 | P16: =sum(P10:P14) -> 504 | Q16: =sum(Q10:Q14) -> 0 | R16: =sum(R10:R14) -> 555 | S16: =sum(S10:S14) -> 0 | T16: =sum(T10:T14) -> 610 | U16: =T16+R16+P16+N16+L16+I16+G16+E16 -> 2701
